Workbook

Sheet 区域运费DHL
A1: 国家地区 | B1: 代码 | C1: 0.5 | D1: 1 | E1: 1.5 | F1: 2 | G1: 2.5 | H1: 3 | I1: 3.5 | J1: 4 | K1: 4.5 | L1: 5 | M1: 5.5 | N1: 6 | O1: 6.5 | P1: 7 | Q1: 7.5 | R1: 8 | S1: 8.5 | T1: 9 | U1: 9.5 | V1: 10 | W1: 10.5 | X1: 11 | Y1: 11.5 | Z1: 12 | AA1: 12.5 | AB1: 13 | AC1: 13.5 | AD1: 14 | AE1: 14.5 | AF1: 15 | AG1: 15.5 | AH1: 16 | AI1: 16.5 | AJ1: 17 | AK1: 17.5 | AL1: 18 | AM1: 18.5 | AN1: 19 | AO1: 19.5 | AP1: 20 | AQ1: 20.5 | AR1: 21 | AS1: 21.5 | AT1: 22 | AU1: 22.5 | AV1: 23 | AW1: 23.5 | AX1: 24 | AY1: 24.5 | AZ1: 25 | BA1: 25.5 | BB1: 26 | BC1: 26.5 | BD1: 27 | BE1: 27.5 | BF1: 28 | BG1: 28.5 | BH1: 29 | BI1: 29.5 | BJ1: 30
A2: 中国香港特别行政区 | B2: 1 | C2: =广诚DHL运费!C3 -> 97.50 | D2: =广诚DHL运费!C4 -> 118.50 | E2: =广诚DHL运费!C5 -> 139.50 | F2: =广诚DHL运费!C6 -> 160.50 | G2: =广诚DHL运费!C7 -> 181.50 | H2: =广诚DHL运费!C8 -> 201.90 | I2: =广诚DHL运费!C9 -> 222.30 | J2: =广诚DHL运费!C10 -> 242.70 | K2: =广诚DHL运费!C11 -> 263.10 | L2: =广诚DHL运费!C12 -> 283.50 | M2: =广诚DHL运费!C13 -> 302.70 | N2: =广诚DHL运费!C14 -> 321.90 | O2: =广诚DHL运费!C15 -> 341.10 | P2: =广诚DHL运费!C16 -> 360.30 | Q2: =广诚DHL运费!C17 -> 379.50 | R2: =广诚DHL运费!C18 -> 398.70 | S2: =广诚DHL运费!C19 -> 417.90 | T2: =广诚DHL运费!C20 -> 437.10 | U2: =广诚DHL运费!C21 -> 456.30 | V2: =广诚DHL运费!C22 -> 475.50 | W2: =广诚DHL运费!C23 -> 491.10 | X2: =广诚DHL运费!C24 -> 506.70 | Y2: =广诚DHL运费!C25 -> 522.30 | Z2: =广诚DHL运费!C26 -> 537.90 | AA2: =广诚DHL运费!C27 -> 553.50 | AB2: =广诚DHL运费!C28 -> 569.10 | AC2: =广诚DHL运费!C29 -> 584.70 | AD2: =广诚DHL运费!C30 -> 600.30 | AE2: =广诚DHL运费!C31 -> 615.90 | AF2: =广诚DHL运费!C32 -> 631.50 | AG2: =广诚DHL运费!C33 -> 647.10 | AH2: =广诚DHL运费!C34 -> 662.70 | AI2: =广诚DHL运费!C35 -> 678.30 | AJ2: =广诚DHL运费!C36 -> 693.90 | AK2: =广诚DHL运费!C37 -> 709.50 | AL2: =广诚DHL运费!C38 -> 725.10 | AM2: =广诚DHL运费!C39 -> 740.70 | AN2: =广诚DHL运费!C40 -> 756.30 | AO2: =广诚DHL运费!C41 -> 771.90 | AP2: =广诚DHL运费!C42 -> 787.50 | AQ2: 331.37 | AR2: 336.05 | AS2: 340.73 | AT2: 345.41 | AU2: 350.09 | AV2: 354.77 | AW2: 359.45 | AX2: 364.13 | AY2: 368.81 | AZ2: 373.49 | BA2: 378.17 | BB2: 382.85 | BC2: 387.53 | BD2: 392.21 | BE2: 396.89 | BF2: 401.57 | BG2: 406.25 | BH2: 410.93 | BI2: 415.61 | BJ2: 420.29
A3: 中国澳门特别行政区 | B3: 1 | C3: =广诚DHL运费!C3 -> 97.50 | D3: =广诚DHL运费!C4 -> 118.50 | E3: =广诚DHL运费!C5 -> 139.50 | F3: =广诚DHL运费!C6 -> 160.50 | G3: =广诚DHL运费!C7 -> 181.50 | H3: =广诚DHL运费!C8 -> 201.90 | I3: =广诚DHL运费!C9 -> 222.30 | J3: =广诚DHL运费!C10 -> 242.70 | K3: =广诚DHL运费!C11 -> 263.10 | L3: =广诚DHL运费!C12 -> 283.50 | M3: =广诚DHL运费!C13 -> 302.70 | N3: =广诚DHL运费!C14 -> 321.90 | O3: =广诚DHL运费!C15 -> 341.10 | P3: =广诚DHL运费!C16 -> 360.30 | Q3: =广诚DHL运费!C17 -> 379.50 | R3: =广诚DHL运费!C18 -> 398.70 | S3: =广诚DHL运费!C19 -> 417.90 | T3: =广诚DHL运费!C20 -> 437.10 | U3: =广诚DHL运费!C21 -> 456.30 | V3: =广诚DHL运费!C22 -> 475.50 | W3: =广诚DHL运费!C23 -> 491.10 | X3: =广诚DHL运费!C24 -> 506.70 | Y3: =广诚DHL运费!C25 -> 522.30 | Z3: =广诚DHL运费!C26 -> 537.90 | AA3: =广诚DHL运费!C27 -> 553.50 | AB3: =广诚DHL运费!C28 -> 569.10 | AC3: =广诚DHL运费!C29 -> 584.70 | AD3: =广诚DHL运费!C30 -> 600.30 | AE3: =广诚DHL运费!C31 -> 615.90 | AF3: =广诚DHL运费!C32 -> 631.50 | AG3: =广诚DHL运费!C33 -> 647.10 | AH3: =广诚DHL运费!C34 -> 662.70 | AI3: =广诚DHL运费!C35 -> 678.30 | AJ3: =广诚DHL运费!C36 -> 693.90 | AK3: =广诚DHL运费!C37 -> 709.50 | AL3: =广诚DHL运费!C38 -> 725.10 | AM3: =广诚DHL运费!C39 -> 740.70 | AN3: =广诚DHL运费!C40 -> 756.30 | AO3: =广诚DHL运费!C41 -> 771.90 | AP3: =广诚DHL运费!C42 -> 787.50 | AQ3: 331.37 | AR3: 336.05 | AS3: 340.73 | AT3: 345.41 | AU3: 350.09 | AV3: 354.77 | AW3: 359.45 | AX3: 364.13 | AY3: 368.81 | AZ3: 373.49 | BA3: 378.17 | BB3: 382.85 | BC3: 387.53 | BD3: 392.21 | BE3: 396.89 | BF3: 401.57 | BG3: 406.25 | BH3: 410.93 | BI3: 415.61 | BJ3: 420.29
A4: 韩国 | B4: 2 | C4: =广诚DHL运费!D3 -> 132.00 | D4: =广诚DHL运费!D4 -> 162.30 | E4: =广诚DHL运费!D5 -> 192.60 | F4: =广诚DHL运费!D6 -> 222.90 | G4: =广诚DHL运费!D7 -> 253.20 | H4: =广诚DHL运费!D8 -> 283.20 | I4: =广诚DHL运费!D9 -> 313.20 | J4: =广诚DHL运费!D10 -> 343.20 | K4: =广诚DHL运费!D11 -> 373.20 | L4: =广诚DHL运费!D12 -> 403.20 | M4: =广诚DHL运费!D13 -> 431.70 | N4: =广诚DHL运费!D14 -> 460.20 | O4: =广诚DHL运费!D15 -> 488.70 | P4: =广诚DHL运费!D16 -> 517.20 | Q4: =广诚DHL运费!D17 -> 545.70 | R4: =广诚DHL运费!D18 -> 574.20 | S4: =广诚DHL运费!D19 -> 602.70 | T4: =广诚DHL运费!D20 -> 631.20 | U4: =广诚DHL运费!D21 -> 659.70 | V4: =广诚DHL运费!D22 -> 688.20 | W4: =广诚DHL运费!D23 -> 712.80 | X4: =广诚DHL运费!D24 -> 737.40 | Y4: =广诚DHL运费!D25 -> 762.00 | Z4: =广诚DHL运费!D26 -> 786.60 | AA4: =广诚DHL运费!D27 -> 811.20 | AB4: =广诚DHL运费!D28 -> 835.80 | AC4: =广诚DHL运费!D29 -> 860.40 | AD4: =广诚DHL运费!D30 -> 885.00 | AE4: =广诚DHL运费!D31 -> 909.60 | AF4: =广诚DHL运费!D32 -> 934.20 | AG4: =广诚DHL运费!D33 -> 958.80 | AH4: =广诚DHL运费!D34 -> 983.40 | AI4: =广诚DHL运费!D35 -> 1,008.00 | AJ4: =广诚DHL运费!D36 -> 1,032.60 | AK4: =广诚DHL运费!D37 -> 1,057.20 | AL4: =广诚DHL运费!D38 -> 1,081.80 | AM4: =广诚DHL运费!D39 -> 1,106.40 | AN4: =广诚DHL运费!D40 -> 1,131.00 | AO4: =广诚DHL运费!D41 -> 1,155.60 | AP4: =广诚DHL运费!D42 -> 1,180.20 | AQ4: 423.83 | AR4: 433.73 | AS4: 443.63 | AT4: 453.53 | AU4: 463.43 | AV4: 473.33 | AW4: 483.23 | AX4: 493.13 | AY4: 503.03 | AZ4: 512.93 | BA4: 522.83 | BB4: 532.73 | BC4: 542.63 | BD4: 552.53 | BE4: 562.43 | BF4: 572.33 | BG4: 582.23 | BH4: 592.13 | BI4: 602.03 | BJ4: 611.93
A5: 中国台湾地区 | B5: 2 | C5: =广诚DHL运费!D3 -> 132.00 | D5: =广诚DHL运费!D4 -> 162.30 | E5: =广诚DHL运费!D5 -> 192.60 | F5: =广诚DHL运费!D6 -> 222.90 | G5: =广诚DHL运费!D7 -> 253.20 | H5: =广诚DHL运费!D8 -> 283.20 | I5: =广诚DHL运费!D9 -> 313.20 | J5: =广诚DHL运费!D10 -> 343.20 | K5: =广诚DHL运费!D11 -> 373.20 | L5: =广诚DHL运费!D12 -> 403.20 | M5: =广诚DHL运费!D13 -> 431.70 | N5: =广诚DHL运费!D14 -> 460.20 | O5: =广诚DHL运费!D15 -> 488.70 | P5: =广诚DHL运费!D16 -> 517.20 | Q5: =广诚DHL运费!D17 -> 545.70 | R5: =广诚DHL运费!D18 -> 574.20 | S5: =广诚DHL运费!D19 -> 602.70 | T5: =广诚DHL运费!D20 -> 631.20 | U5: =广诚DHL运费!D21 -> 659.70 | V5: =广诚DHL运费!D22 -> 688.20 | W5: =广诚DHL运费!D23 -> 712.80 | X5: =广诚DHL运费!D24 -> 737.40 | Y5: =广诚DHL运费!D25 -> 762.00 | Z5: =广诚DHL运费!D26 -> 786.60 | AA5: =广诚DHL运费!D27 -> 811.20 | AB5: =广诚DHL运费!D28 -> 835.80 | AC5: =广诚DHL运费!D29 -> 860.40 | AD5: =广诚DHL运费!D30 -> 885.00 | AE5: =广诚DHL运费!D31 -> 909.60 | AF5: =广诚DHL运费!D32 -> 934.20 | AG5: =广诚DHL运费!D33 -> 958.80 | AH5: =广诚DHL运费!D34 -> 983.40 | AI5: =广诚DHL运费!D35 -> 1,008.00 | AJ5: =广诚DHL运费!D36 -> 1,032.60 | AK5: =广诚DHL运费!D37 -> 1,057.20 | AL5: =广诚DHL运费!D38 -> 1,081.80 | AM5: =广诚DHL运费!D39 -> 1,106.40 | AN5: =广诚DHL运费!D40 -> 1,131.00 | AO5: =广诚DHL运费!D41 -> 1,155.60 | AP5: =广诚DHL运费!D42 -> 1,180.20 | AQ5: 423.83 | AR5: 433.73 | AS5: 443.63 | AT5: 453.53 | AU5: 463.43 | AV5: 473.33 | AW5: 483.23 | AX5: 493.13 | AY5: 503.03 | AZ5: 512.93 | BA5: 522.83 | BB5: 532.73 | BC5: 542.63 | BD5: 552.53 | BE5: 562.43 | BF5: 572.33 | BG5: 582.23 | BH5: 592.13 | BI5: 602.03 | BJ5: 611.93
A6: 日本 | B6: 3 | C6: =广诚DHL运费!E3 -> 123.30 | D6: =广诚DHL运费!E4 -> 156.00 | E6: =广诚DHL运费!E5 -> 188.70 | F6: =广诚DHL运费!E6 -> 221.40 | G6: =广诚DHL运费!E7 -> 254.10 | H6: =广诚DHL运费!E8 -> 284.10 | I6: =广诚DHL运费!E9 -> 314.10 | J6: =广诚DHL运费!E10 -> 344.10 | K6: =广诚DHL运费!E11 -> 374.10 | L6: =广诚DHL运费!E12 -> 404.10 | M6: =广诚DHL运费!E13 -> 433.50 | N6: =广诚DHL运费!E14 -> 462.90 | O6: =广诚DHL运费!E15 -> 492.30 | P6: =广诚DHL运费!E16 -> 521.70 | Q6: =广诚DHL运费!E17 -> 551.10 | R6: =广诚DHL运费!E18 -> 580.50 | S6: =广诚DHL运费!E19 -> 609.90 | T6: =广诚DHL运费!E20 -> 639.30 | U6: =广诚DHL运费!E21 -> 668.70 | V6: =广诚DHL运费!E22 -> 698.10 | W6: =广诚DHL运费!E23 -> 725.70 | X6: =广诚DHL运费!E24 -> 753.30 | Y6: =广诚DHL运费!E25 -> 780.90 | Z6: =广诚DHL运费!E26 -> 808.50 | AA6: =广诚DHL运费!E27 -> 836.10 | AB6: =广诚DHL运费!E28 -> 863.70 | AC6: =广诚DHL运费!E29 -> 891.30 | AD6: =广诚DHL运费!E30 -> 918.90 | AE6: =广诚DHL运费!E31 -> 946.50 | AF6: =广诚DHL运费!E32 -> 974.10 | AG6: =广诚DHL运费!E33 -> 1,001.70 | AH6: =广诚DHL运费!E34 -> 1,029.30 | AI6: =广诚DHL运费!E35 -> 1,056.90 | AJ6: =广诚DHL运费!E36 -> 1,084.50 | AK6: =广诚DHL运费!E37 -> 1,112.10 | AL6: =广诚DHL运费!E38 -> 1,139.70 | AM6: =广诚DHL运费!E39 -> 1,167.30 | AN6: =广诚DHL运费!E40 -> 1,194.90 | AO6: =广诚DHL运费!E41 -> 1,222.50 | AP6: =广诚DHL运费!E42 -> 1,250.10 | AQ6: 486.6 | AR6: 496.44 | AS6: 506.28 | AT6: 516.12 | AU6: 525.96 | AV6: 535.8 | AW6: 545.64 | AX6: 555.48 | AY6: 565.32 | AZ6: 575.16 | BA6: 585 | BB6: 594.84 | BC6: 604.68 | BD6: 614.52 | BE6: 624.36 | BF6: 634.2 | BG6: 644.04 | BH6: 653.88 | BI6: 663.72 | BJ6: 673.56
A7: 文莱 | B7: 4 | C7: =广诚DHL运费!F3 -> 146.40 | D7: =广诚DHL运费!F4 -> 178.50 | E7: =广诚DHL运费!F5 -> 210.60 | F7: =广诚DHL运费!F6 -> 242.70 | G7: =广诚DHL运费!F7 -> 275.40 | H7: =广诚DHL运费!F8 -> 306.60 | I7: =广诚DHL运费!F9 -> 337.80 | J7: =广诚DHL运费!F10 -> 369.00 | K7: =广诚DHL运费!F11 -> 400.20 | L7: =广诚DHL运费!F12 -> 431.40 | M7: =广诚DHL运费!F13 -> 462.30 | N7: =广诚DHL运费!F14 -> 493.20 | O7: =广诚DHL运费!F15 -> 524.10 | P7: =广诚DHL运费!F16 -> 555.00 | Q7: =广诚DHL运费!F17 -> 585.90 | R7: =广诚DHL运费!F18 -> 616.80 | S7: =广诚DHL运费!F19 -> 647.70 | T7: =广诚DHL运费!F20 -> 678.60 | U7: =广诚DHL运费!F21 -> 709.50 | V7: =广诚DHL运费!F22 -> 740.40 | W7: =广诚DHL运费!F23 -> 771.00 | X7: =广诚DHL运费!F24 -> 801.60 | Y7: =广诚DHL运费!F25 -> 832.20 | Z7: =广诚DHL运费!F26 -> 862.80 | AA7: =广诚DHL运费!F27 -> 893.40 | AB7: =广诚DHL运费!F28 -> 924.00 | AC7: =广诚DHL运费!F29 -> 954.60 | AD7: =广诚DHL运费!F30 -> 985.20 | AE7: =广诚DHL运费!F31 -> 1,015.80 | AF7: =广诚DHL运费!F32 -> 1,046.40 | AG7: =广诚DHL运费!F33 -> 1,077.00 | AH7: =广诚DHL运费!F34 -> 1,107.60 | AI7: =广诚DHL运费!F35 -> 1,138.20 | AJ7: =广诚DHL运费!F36 -> 1,168.80 | AK7: =广诚DHL运费!F37 -> 1,199.40 | AL7: =广诚DHL运费!F38 -> 1,230.00 | AM7: =广诚DHL运费!F39 -> 1,260.60 | AN7: =广诚DHL运费!F40 -> 1,291.20 | AO7: =广诚DHL运费!F41 -> 1,321.80 | AP7: =广诚DHL运费!F42 -> 1,352.40 | AQ7: 569.01 | AR7: 580.32 | AS7: 591.63 | AT7: 602.94 | AU7: 614.25 | AV7: 625.56 | AW7: 636.87 | AX7: 648.18 | AY7: 659.49 | AZ7: 670.8 | BA7: 682.11 | BB7: 693.42 | BC7: 704.73 | BD7: 716.04 | BE7: 727.35 | BF7: 738.66 | BG7: 749.97 | BH7: 761.28 | BI7: 772.59 | BJ7: 783.9
A8: 印度尼西亚 | B8: 4 | C8: =广诚DHL运费!F3 -> 146.40 | D8: =广诚DHL运费!F4 -> 178.50 | E8: =广诚DHL运费!F5 -> 210.60 | F8: =广诚DHL运费!F6 -> 242.70 | G8: =广诚DHL运费!F7 -> 275.40 | H8: =广诚DHL运费!F8 -> 306.60 | I8: =广诚DHL运费!F9 -> 337.80 | J8: =广诚DHL运费!F10 -> 369.00 | K8: =广诚DHL运费!F11 -> 400.20 | L8: =广诚DHL运费!F12 -> 431.40 | M8: =广诚DHL运费!F13 -> 462.30 | N8: =广诚DHL运费!F14 -> 493.20 | O8: =广诚DHL运费!F15 -> 524.10 | P8: =广诚DHL运费!F16 -> 555.00 | Q8: =广诚DHL运费!F17 -> 585.90 | R8: =广诚DHL运费!F18 -> 616.80 | S8: =广诚DHL运费!F19 -> 647.70 | T8: =广诚DHL运费!F20 -> 678.60 | U8: =广诚DHL运费!F21 -> 709.50 | V8: =广诚DHL运费!F22 -> 740.40 | W8: =广诚DHL运费!F23 -> 771.00 | X8: =广诚DHL运费!F24 -> 801.60 | Y8: =广诚DHL运费!F25 -> 832.20 | Z8: =广诚DHL运费!F26 -> 862.80 | AA8: =广诚DHL运费!F27 -> 893.40 | AB8: =广诚DHL运费!F28 -> 924.00 | AC8: =广诚DHL运费!F29 -> 954.60 | AD8: =广诚DHL运费!F30 -> 985.20 | AE8: =广诚DHL运费!F31 -> 1,015.80 | AF8: =广诚DHL运费!F32 -> 1,046.40 | AG8: =广诚DHL运费!F33 -> 1,077.00 | AH8: =广诚DHL运费!F34 -> 1,107.60 | AI8: =广诚DHL运费!F35 -> 1,138.20 | AJ8: =广诚DHL运费!F36 -> 1,168.80 | AK8: =广诚DHL运费!F37 -> 1,199.40 | AL8: =广诚DHL运费!F38 -> 1,230.00 | AM8: =广诚DHL运费!F39 -> 1,260.60 | AN8: =广诚DHL运费!F40 -> 1,291.20 | AO8: =广诚DHL运费!F41 -> 1,321.80 | AP8: =广诚DHL运费!F42 -> 1,352.40 | AQ8: 569.01 | AR8: 580.32 | AS8: 591.63 | AT8: 602.94 | AU8: 614.25 | AV8: 625.56 | AW8: 636.87 | AX8: 648.18 | AY8: 659.49 | AZ8: 670.8 | BA8: 682.11 | BB8: 693.42 | BC8: 704.73 | BD8: 716.04 | BE8: 727.35 | BF8: 738.66 | BG8: 749.97 | BH8: 761.28 | BI8: 772.59 | BJ8: 783.9
A9: 柬埔寨 | B9: 4 | C9: =广诚DHL运费!F3 -> 146.40 | D9: =广诚DHL运费!F4 -> 178.50 | E9: =广诚DHL运费!F5 -> 210.60 | F9: =广诚DHL运费!F6 -> 242.70 | G9: =广诚DHL运费!F7 -> 275.40 | H9: =广诚DHL运费!F8 -> 306.60 | I9: =广诚DHL运费!F9 -> 337.80 | J9: =广诚DHL运费!F10 -> 369.00 | K9: =广诚DHL运费!F11 -> 400.20 | L9: =广诚DHL运费!F12 -> 431.40 | M9: =广诚DHL运费!F13 -> 462.30 | N9: =广诚DHL运费!F14 -> 493.20 | O9: =广诚DHL运费!F15 -> 524.10 | P9: =广诚DHL运费!F16 -> 555.00 | Q9: =广诚DHL运费!F17 -> 585.90 | R9: =广诚DHL运费!F18 -> 616.80 | S9: =广诚DHL运费!F19 -> 647.70 | T9: =广诚DHL运费!F20 -> 678.60 | U9: =广诚DHL运费!F21 -> 709.50 | V9: =广诚DHL运费!F22 -> 740.40 | W9: =广诚DHL运费!F23 -> 771.00 | X9: =广诚DHL运费!F24 -> 801.60 | Y9: =广诚DHL运费!F25 -> 832.20 | Z9: =广诚DHL运费!F26 -> 862.80 | AA9: =广诚DHL运费!F27 -> 893.40 | AB9: =广诚DHL运费!F28 -> 924.00 | AC9: =广诚DHL运费!F29 -> 954.60 | AD9: =广诚DHL运费!F30 -> 985.20 | AE9: =广诚DHL运费!F31 -> 1,015.80 | AF9: =广诚DHL运费!F32 -> 1,046.40 | AG9: =广诚DHL运费!F33 -> 1,077.00 | AH9: =广诚DHL运费!F34 -> 1,107.60 | AI9: =广诚DHL运费!F35 -> 1,138.20 | AJ9: =广诚DHL运费!F36 -> 1,168.80 | AK9: =广诚DHL运费!F37 -> 1,199.40 | AL9: =广诚DHL运费!F38 -> 1,230.00 | AM9: =广诚DHL运费!F39 -> 1,260.60 | AN9: =广诚DHL运费!F40 -> 1,291.20 | AO9: =广诚DHL运费!F41 -> 1,321.80 | AP9: =广诚DHL运费!F42 -> 1,352.40 | AQ9: 569.01 | AR9: 580.32 | AS9: 591.63 | AT9: 602.94 | AU9: 614.25 | AV9: 625.56 | AW9: 636.87 | AX9: 648.18 | AY9: 659.49 | AZ9: 670.8 | BA9: 682.11 | BB9: 693.42 | BC9: 704.73 | BD9: 716.04 | BE9: 727.35 | BF9: 738.66 | BG9: 749.97 | BH9: 761.28 | BI9: 772.59 | BJ9: 783.9
A10: 老挝 | B10: 4 | C10: =广诚DHL运费!F3 -> 146.40 | D10: =广诚DHL运费!F4 -> 178.50 | E10: =广诚DHL运费!F5 -> 210.60 | F10: =广诚DHL运费!F6 -> 242.70 | G10: =广诚DHL运费!F7 -> 275.40 | H10: =广诚DHL运费!F8 -> 306.60 | I10: =广诚DHL运费!F9 -> 337.80 | J10: =广诚DHL运费!F10 -> 369.00 | K10: =广诚DHL运费!F11 -> 400.20 | L10: =广诚DHL运费!F12 -> 431.40 | M10: =广诚DHL运费!F13 -> 462.30 | N10: =广诚DHL运费!F14 -> 493.20 | O10: =广诚DHL运费!F15 -> 524.10 | P10: =广诚DHL运费!F16 -> 555.00 | Q10: =广诚DHL运费!F17 -> 585.90 | R10: =广诚DHL运费!F18 -> 616.80 | S10: =广诚DHL运费!F19 -> 647.70 | T10: =广诚DHL运费!F20 -> 678.60 | U10: =广诚DHL运费!F21 -> 709.50 | V10: =广诚DHL运费!F22 -> 740.40 | W10: =广诚DHL运费!F23 -> 771.00 | X10: =广诚DHL运费!F24 -> 801.60 | Y10: =广诚DHL运费!F25 -> 832.20 | Z10: =广诚DHL运费!F26 -> 862.80 | AA10: =广诚DHL运费!F27 -> 893.40 | AB10: =广诚DHL运费!F28 -> 924.00 | AC10: =广诚DHL运费!F29 -> 954.60 | AD10: =广诚DHL运费!F30 -> 985.20 | AE10: =广诚DHL运费!F31 -> 1,015.80 | AF10: =广诚DHL运费!F32 -> 1,046.40 | AG10: =广诚DHL运费!F33 -> 1,077.00 | AH10: =广诚DHL运费!F34 -> 1,107.60 | AI10: =广诚DHL运费!F35 -> 1,138.20 | AJ10: =广诚DHL运费!F36 -> 1,168.80 | AK10: =广诚DHL运费!F37 -> 1,199.40 | AL10: =广诚DHL运费!F38 -> 1,230.00 | AM10: =广诚DHL运费!F39 -> 1,260.60 | AN10: =广诚DHL运费!F40 -> 1,291.20 | AO10: =广诚DHL运费!F41 -> 1,321.80 | AP10: =广诚DHL运费!F42 -> 1,352.40 | AQ10: 569.01 | AR10: 580.32 | AS10: 591.63 | AT10: 602.94 | AU10: 614.25 | AV10: 625.56 | AW10: 636.87 | AX10: 648.18 | AY10: 659.49 | AZ10: 670.8 | BA10: 682.11 | BB10: 693.42 | BC10: 704.73 | BD10: 716.04 | BE10: 727.35 | BF10: 738.66 | BG10: 749.97 | BH10: 761.28 | BI10: 772.59 | BJ10: 783.9
A11: 马来西亚 | B11: 4 | C11: =广诚DHL运费!F3 -> 146.40 | D11: =广诚DHL运费!F4 -> 178.50 | E11: =广诚DHL运费!F5 -> 210.60 | F11: =广诚DHL运费!F6 -> 242.70 | G11: =广诚DHL运费!F7 -> 275.40 | H11: =广诚DHL运费!F8 -> 306.60 | I11: =广诚DHL运费!F9 -> 337.80 | J11: =广诚DHL运费!F10 -> 369.00 | K11: =广诚DHL运费!F11 -> 400.20 | L11: =广诚DHL运费!F12 -> 431.40 | M11: =广诚DHL运费!F13 -> 462.30 | N11: =广诚DHL运费!F14 -> 493.20 | O11: =广诚DHL运费!F15 -> 524.10 | P11: =广诚DHL运费!F16 -> 555.00 | Q11: =广诚DHL运费!F17 -> 585.90 | R11: =广诚DHL运费!F18 -> 616.80 | S11: =广诚DHL运费!F19 -> 647.70 | T11: =广诚DHL运费!F20 -> 678.60 | U11: =广诚DHL运费!F21 -> 709.50 | V11: =广诚DHL运费!F22 -> 740.40 | W11: =广诚DHL运费!F23 -> 771.00 | X11: =广诚DHL运费!F24 -> 801.60 | Y11: =广诚DHL运费!F25 -> 832.20 | Z11: =广诚DHL运费!F26 -> 862.80 | AA11: =广诚DHL运费!F27 -> 893.40 | AB11: =广诚DHL运费!F28 -> 924.00 | AC11: =广诚DHL运费!F29 -> 954.60 | AD11: =广诚DHL运费!F30 -> 985.20 | AE11: =广诚DHL运费!F31 -> 1,015.80 | AF11: =广诚DHL运费!F32 -> 1,046.40 | AG11: =广诚DHL运费!F33 -> 1,077.00 | AH11: =广诚DHL运费!F34 -> 1,107.60 | AI11: =广诚DHL运费!F35 -> 1,138.20 | AJ11: =广诚DHL运费!F36 -> 1,168.80 | AK11: =广诚DHL运费!F37 -> 1,199.40 | AL11: =广诚DHL运费!F38 -> 1,230.00 | AM11: =广诚DHL运费!F39 -> 1,260.60 | AN11: =广诚DHL运费!F40 -> 1,291.20 | AO11: =广诚DHL运费!F41 -> 1,321.80 | AP11: =广诚DHL运费!F42 -> 1,352.40 | AQ11: 569.01 | AR11: 580.32 | AS11: 591.63 | AT11: 602.94 | AU11: 614.25 | AV11: 625.56 | AW11: 636.87 | AX11: 648.18 | AY11: 659.49 | AZ11: 670.8 | BA11: 682.11 | BB11: 693.42 | BC11: 704.73 | BD11: 716.04 | BE11: 727.35 | BF11: 738.66 | BG11: 749.97 | BH11: 761.28 | BI11: 772.59 | BJ11: 783.9
A12: 菲律宾 | B12: 4 | C12: =广诚DHL运费!F3 -> 146.40 | D12: =广诚DHL运费!F4 -> 178.50 | E12: =广诚DHL运费!F5 -> 210.60 | F12: =广诚DHL运费!F6 -> 242.70 | G12: =广诚DHL运费!F7 -> 275.40 | H12: =广诚DHL运费!F8 -> 306.60 | I12: =广诚DHL运费!F9 -> 337.80 | J12: =广诚DHL运费!F10 -> 369.00 | K12: =广诚DHL运费!F11 -> 400.20 | L12: =广诚DHL运费!F12 -> 431.40 | M12: =广诚DHL运费!F13 -> 462.30 | N12: =广诚DHL运费!F14 -> 493.20 | O12: =广诚DHL运费!F15 -> 524.10 | P12: =广诚DHL运费!F16 -> 555.00 | Q12: =广诚DHL运费!F17 -> 585.90 | R12: =广诚DHL运费!F18 -> 616.80 | S12: =广诚DHL运费!F19 -> 647.70 | T12: =广诚DHL运费!F20 -> 678.60 | U12: =广诚DHL运费!F21 -> 709.50 | V12: =广诚DHL运费!F22 -> 740.40 | W12: =广诚DHL运费!F23 -> 771.00 | X12: =广诚DHL运费!F24 -> 801.60 | Y12: =广诚DHL运费!F25 -> 832.20 | Z12: =广诚DHL运费!F26 -> 862.80 | AA12: =广诚DHL运费!F27 -> 893.40 | AB12: =广诚DHL运费!F28 -> 924.00 | AC12: =广诚DHL运费!F29 -> 954.60 | AD12: =广诚DHL运费!F30 -> 985.20 | AE12: =广诚DHL运费!F31 -> 1,015.80 | AF12: =广诚DHL运费!F32 -> 1,046.40 | AG12: =广诚DHL运费!F33 -> 1,077.00 | AH12: =广诚DHL运费!F34 -> 1,107.60 | AI12: =广诚DHL运费!F35 -> 1,138.20 | AJ12: =广诚DHL运费!F36 -> 1,168.80 | AK12: =广诚DHL运费!F37 -> 1,199.40 | AL12: =广诚DHL运费!F38 -> 1,230.00 | AM12: =广诚DHL运费!F39 -> 1,260.60 | AN12: =广诚DHL运费!F40 -> 1,291.20 | AO12: =广诚DHL运费!F41 -> 1,321.80 | AP12: =广诚DHL运费!F42 -> 1,352.40 | AQ12: 569.01 | AR12: 580.32 | AS12: 591.63 | AT12: 602.94 | AU12: 614.25 | AV12: 625.56 | AW12: 636.87 | AX12: 648.18 | AY12: 659.49 | AZ12: 670.8 | BA12: 682.11 | BB12: 693.42 | BC12: 704.73 | BD12: 716.04 | BE12: 727.35 | BF12: 738.66 | BG12: 749.97 | BH12: 761.28 | BI12: 772.59 | BJ12: 783.9
A13: 新加坡 | B13: 4 | C13: =广诚DHL运费!F3 -> 146.40 | D13: =广诚DHL运费!F4 -> 178.50 | E13: =广诚DHL运费!F5 -> 210.60 | F13: =广诚DHL运费!F6 -> 242.70 | G13: =广诚DHL运费!F7 -> 275.40 | H13: =广诚DHL运费!F8 -> 306.60 | I13: =广诚DHL运费!F9 -> 337.80 | J13: =广诚DHL运费!F10 -> 369.00 | K13: =广诚DHL运费!F11 -> 400.20 | L13: =广诚DHL运费!F12 -> 431.40 | M13: =广诚DHL运费!F13 -> 462.30 | N13: =广诚DHL运费!F14 -> 493.20 | O13: =广诚DHL运费!F15 -> 524.10 | P13: =广诚DHL运费!F16 -> 555.00 | Q13: =广诚DHL运费!F17 -> 585.90 | R13: =广诚DHL运费!F18 -> 616.80 | S13: =广诚DHL运费!F19 -> 647.70 | T13: =广诚DHL运费!F20 -> 678.60 | U13: =广诚DHL运费!F21 -> 709.50 | V13: =广诚DHL运费!F22 -> 740.40 | W13: =广诚DHL运费!F23 -> 771.00 | X13: =广诚DHL运费!F24 -> 801.60 | Y13: =广诚DHL运费!F25 -> 832.20 | Z13: =广诚DHL运费!F26 -> 862.80 | AA13: =广诚DHL运费!F27 -> 893.40 | AB13: =广诚DHL运费!F28 -> 924.00 | AC13: =广诚DHL运费!F29 -> 954.60 | AD13: =广诚DHL运费!F30 -> 985.20 | AE13: =广诚DHL运费!F31 -> 1,015.80 | AF13: =广诚DHL运费!F32 -> 1,046.40 | AG13: =广诚DHL运费!F33 -> 1,077.00 | AH13: =广诚DHL运费!F34 -> 1,107.60 | AI13: =广诚DHL运费!F35 -> 1,138.20 | AJ13: =广诚DHL运费!F36 -> 1,168.80 | AK13: =广诚DHL运费!F37 -> 1,199.40 | AL13: =广诚DHL运费!F38 -> 1,230.00 | AM13: =广诚DHL运费!F39 -> 1,260.60 | AN13: =广诚DHL运费!F40 -> 1,291.20 | AO13: =广诚DHL运费!F41 -> 1,321.80 | AP13: =广诚DHL运费!F42 -> 1,352.40 | AQ13: 569.01 | AR13: 580.32 | AS13: 591.63 | AT13: 602.94 | AU13: 614.25 | AV13: 625.56 | AW13: 636.87 | AX13: 648.18 | AY13: 659.49 | AZ13: 670.8 | BA13: 682.11 | BB13: 693.42 | BC13: 704.73 | BD13: 716.04 | BE13: 727.35 | BF13: 738.66 | BG13: 749.97 | BH13: 761.28 | BI13: 772.59 | BJ13: 783.9
A14: 泰国 | B14: 4 | C14: =广诚DHL运费!F3 -> 146.40 | D14: =广诚DHL运费!F4 -> 178.50 | E14: =广诚DHL运费!F5 -> 210.60 | F14: =广诚DHL运费!F6 -> 242.70 | G14: =广诚DHL运费!F7 -> 275.40 | H14: =广诚DHL运费!F8 -> 306.60 | I14: =广诚DHL运费!F9 -> 337.80 | J14: =广诚DHL运费!F10 -> 369.00 | K14: =广诚DHL运费!F11 -> 400.20 | L14: =广诚DHL运费!F12 -> 431.40 | M14: =广诚DHL运费!F13 -> 462.30 | N14: =广诚DHL运费!F14 -> 493.20 | O14: =广诚DHL运费!F15 -> 524.10 | P14: =广诚DHL运费!F16 -> 555.00 | Q14: =广诚DHL运费!F17 -> 585.90 | R14: =广诚DHL运费!F18 -> 616.80 | S14: =广诚DHL运费!F19 -> 647.70 | T14: =广诚DHL运费!F20 -> 678.60 | U14: =广诚DHL运费!F21 -> 709.50 | V14: =广诚DHL运费!F22 -> 740.40 | W14: =广诚DHL运费!F23 -> 771.00 | X14: =广诚DHL运费!F24 -> 801.60 | Y14: =广诚DHL运费!F25 -> 832.20 | Z14: =广诚DHL运费!F26 -> 862.80 | AA14: =广诚DHL运费!F27 -> 893.40 | AB14: =广诚DHL运费!F28 -> 924.00 | AC14: =广诚DHL运费!F29 -> 954.60 | AD14: =广诚DHL运费!F30 -> 985.20 | AE14: =广诚DHL运费!F31 -> 1,015.80 | AF14: =广诚DHL运费!F32 -> 1,046.40 | AG14: =广诚DHL运费!F33 -> 1,077.00 | AH14: =广诚DHL运费!F34 -> 1,107.60 | AI14: =广诚DHL运费!F35 -> 1,138.20 | AJ14: =广诚DHL运费!F36 -> 1,168.80 | AK14: =广诚DHL运费!F37 -> 1,199.40 | AL14: =广诚DHL运费!F38 -> 1,230.00 | AM14: =广诚DHL运费!F39 -> 1,260.60 | AN14: =广诚DHL运费!F40 -> 1,291.20 | AO14: =广诚DHL运费!F41 -> 1,321.80 | AP14: =广诚DHL运费!F42 -> 1,352.40 | AQ14: 569.01 | AR14: 580.32 | AS14: 591.63 | AT14: 602.94 | AU14: 614.25 | AV14: 625.56 | AW14: 636.87 | AX14: 648.18 | AY14: 659.49 | AZ14: 670.8 | BA14: 682.11 | BB14: 693.42 | BC14: 704.73 | BD14: 716.04 | BE14: 727.35 | BF14: 738.66 | BG14: 749.97 | BH14: 761.28 | BI14: 772.59 | BJ14: 783.9
A15: 越南 | B15: 4 | C15: =广诚DHL运费!F3 -> 146.40 | D15: =广诚DHL运费!F4 -> 178.50 | E15: =广诚DHL运费!F5 -> 210.60 | F15: =广诚DHL运费!F6 -> 242.70 | G15: =广诚DHL运费!F7 -> 275.40 | H15: =广诚DHL运费!F8 -> 306.60 | I15: =广诚DHL运费!F9 -> 337.80 | J15: =广诚DHL运费!F10 -> 369.00 | K15: =广诚DHL运费!F11 -> 400.20 | L15: =广诚DHL运费!F12 -> 431.40 | M15: =广诚DHL运费!F13 -> 462.30 | N15: =广诚DHL运费!F14 -> 493.20 | O15: =广诚DHL运费!F15 -> 524.10 | P15: =广诚DHL运费!F16 -> 555.00 | Q15: =广诚DHL运费!F17 -> 585.90 | R15: =广诚DHL运费!F18 -> 616.80 | S15: =广诚DHL运费!F19 -> 647.70 | T15: =广诚DHL运费!F20 -> 678.60 | U15: =广诚DHL运费!F21 -> 709.50 | V15: =广诚DHL运费!F22 -> 740.40 | W15: =广诚DHL运费!F23 -> 771.00 | X15: =广诚DHL运费!F24 -> 801.60 | Y15: =广诚DHL运费!F25 -> 832.20 | Z15: =广诚DHL运费!F26 -> 862.80 | AA15: =广诚DHL运费!F27 -> 893.40 | AB15: =广诚DHL运费!F28 -> 924.00 | AC15: =广诚DHL运费!F29 -> 954.60 | AD15: =广诚DHL运费!F30 -> 985.20 | AE15: =广诚DHL运费!F31 -> 1,015.80 | AF15: =广诚DHL运费!F32 -> 1,046.40 | AG15: =广诚DHL运费!F33 -> 1,077.00 | AH15: =广诚DHL运费!F34 -> 1,107.60 | AI15: =广诚DHL运费!F35 -> 1,138.20 | AJ15: =广诚DHL运费!F36 -> 1,168.80 | AK15: =广诚DHL运费!F37 -> 1,199.40 | AL15: =广诚DHL运费!F38 -> 1,230.00 | AM15: =广诚DHL运费!F39 -> 1,260.60 | AN15: =广诚DHL运费!F40 -> 1,291.20 | AO15: =广诚DHL运费!F41 -> 1,321.80 | AP15: =广诚DHL运费!F42 -> 1,352.40 | AQ15: 569.01 | AR15: 580.32 | AS15: 591.63 | AT15: 602.94 | AU15: 614.25 | AV15: 625.56 | AW15: 636.87 | AX15: 648.18 | AY15: 659.49 | AZ15: 670.8 | BA15: 682.11 | BB15: 693.42 | BC15: 704.73 | BD15: 716.04 | BE15: 727.35 | BF15: 738.66 | BG15: 749.97 | BH15: 761.28 | BI15: 772.59 | BJ15: 783.9
A16: 澳大利亚 | B16: 5 | C16: =广诚DHL运费!G3 -> 147.30 | D16: =广诚DHL运费!G4 -> 193.50 | E16: =广诚DHL运费!G5 -> 239.70 | F16: =广诚DHL运费!G6 -> 285.90 | G16: =广诚DHL运费!G7 -> 332.10 | H16: =广诚DHL运费!G8 -> 376.20 | I16: =广诚DHL运费!G9 -> 420.30 | J16: =广诚DHL运费!G10 -> 464.40 | K16: =广诚DHL运费!G11 -> 508.50 | L16: =广诚DHL运费!G12 -> 552.60 | M16: =广诚DHL运费!G13 -> 592.50 | N16: =广诚DHL运费!G14 -> 632.40 | O16: =广诚DHL运费!G15 -> 672.30 | P16: =广诚DHL运费!G16 -> 712.20 | Q16: =广诚DHL运费!G17 -> 752.10 | R16: =广诚DHL运费!G18 -> 792.00 | S16: =广诚DHL运费!G19 -> 831.90 | T16: =广诚DHL运费!G20 -> 871.80 | U16: =广诚DHL运费!G21 -> 911.70 | V16: =广诚DHL运费!G22 -> 951.60 | W16: =广诚DHL运费!G23 -> 988.80 | X16: =广诚DHL运费!G24 -> 1,026.00 | Y16: =广诚DHL运费!G25 -> 1,063.20 | Z16: =广诚DHL运费!G26 -> 1,100.40 | AA16: =广诚DHL运费!G27 -> 1,137.60 | AB16: =广诚DHL运费!G28 -> 1,174.80 | AC16: =广诚DHL运费!G29 -> 1,212.00 | AD16: =广诚DHL运费!G30 -> 1,249.20 | AE16: =广诚DHL运费!G31 -> 1,286.40 | AF16: =广诚DHL运费!G32 -> 1,323.60 | AG16: =广诚DHL运费!G33 -> 1,360.80 | AH16: =广诚DHL运费!G34 -> 1,398.00 | AI16: =广诚DHL运费!G35 -> 1,435.20 | AJ16: =广诚DHL运费!G36 -> 1,472.40 | AK16: =广诚DHL运费!G37 -> 1,509.60 | AL16: =广诚DHL运费!G38 -> 1,546.80 | AM16: =广诚DHL运费!G39 -> 1,584.00 | AN16: =广诚DHL运费!G40 -> 1,621.20 | AO16: =广诚DHL运费!G41 -> 1,658.40 | AP16: =广诚DHL运费!G42 -> 1,695.60 | AQ16: 1046.14 | AR16: 1068.94 | AS16: 1091.74 | AT16: 1114.54 | AU16: 1137.34 | AV16: 1160.14 | AW16: 1182.94 | AX16: 1205.74 | AY16: 1228.54 | AZ16: 1251.34 | BA16: 1274.14 | BB16: 1296.94 | BC16: 1319.74 | BD16: 1342.54 | BE16: 1365.34 | BF16: 1388.14 | BG16: 1410.94 | BH16: 1433.74 | BI16: 1456.54 | BJ16: 1479.34
A17: 新西兰 | B17: 5 | C17: =广诚DHL运费!G3 -> 147.30 | D17: =广诚DHL运费!G4 -> 193.50 | E17: =广诚DHL运费!G5 -> 239.70 | F17: =广诚DHL运费!G6 -> 285.90 | G17: =广诚DHL运费!G7 -> 332.10 | H17: =广诚DHL运费!G8 -> 376.20 | I17: =广诚DHL运费!G9 -> 420.30 | J17: =广诚DHL运费!G10 -> 464.40 | K17: =广诚DHL运费!G11 -> 508.50 | L17: =广诚DHL运费!G12 -> 552.60 | M17: =广诚DHL运费!G13 -> 592.50 | N17: =广诚DHL运费!G14 -> 632.40 | O17: =广诚DHL运费!G15 -> 672.30 | P17: =广诚DHL运费!G16 -> 712.20 | Q17: =广诚DHL运费!G17 -> 752.10 | R17: =广诚DHL运费!G18 -> 792.00 | S17: =广诚DHL运费!G19 -> 831.90 | T17: =广诚DHL运费!G20 -> 871.80 | U17: =广诚DHL运费!G21 -> 911.70 | V17: =广诚DHL运费!G22 -> 951.60 | W17: =广诚DHL运费!G23 -> 988.80 | X17: =广诚DHL运费!G24 -> 1,026.00 | Y17: =广诚DHL运费!G25 -> 1,063.20 | Z17: =广诚DHL运费!G26 -> 1,100.40 | AA17: =广诚DHL运费!G27 -> 1,137.60 | AB17: =广诚DHL运费!G28 -> 1,174.80 | AC17: =广诚DHL运费!G29 -> 1,212.00 | AD17: =广诚DHL运费!G30 -> 1,249.20 | AE17: =广诚DHL运费!G31 -> 1,286.40 | AF17: =广诚DHL运费!G32 -> 1,323.60 | AG17: =广诚DHL运费!G33 -> 1,360.80 | AH17: =广诚DHL运费!G34 -> 1,398.00 | AI17: =广诚DHL运费!G35 -> 1,435.20 | AJ17: =广诚DHL运费!G36 -> 1,472.40 | AK17: =广诚DHL运费!G37 -> 1,509.60 | AL17: =广诚DHL运费!G38 -> 1,546.80 | AM17: =广诚DHL运费!G39 -> 1,584.00 | AN17: =广诚DHL运费!G40 -> 1,621.20 | AO17: =广诚DHL运费!G41 -> 1,658.40 | AP17: =广诚DHL运费!G42 -> 1,695.60 | AQ17: 1046.14 | AR17: 1068.94 | AS17: 1091.74 | AT17: 1114.54 | AU17: 1137.34 | AV17: 1160.14 | AW17: 1182.94 | AX17: 1205.74 | AY17: 1228.54 | AZ17: 1251.34 | BA17: 1274.14 | BB17: 1296.94 | BC17: 1319.74 | BD17: 1342.54 | BE17: 1365.34 | BF17: 1388.14 | BG17: 1410.94 | BH17: 1433.74 | BI17: 1456.54 | BJ17: 1479.34
A18: 加拿大 | B18: 6 | C18: =广诚DHL运费!H3 -> 151.50 | D18: =广诚DHL运费!H4 -> 201.00 | E18: =广诚DHL运费!H5 -> 250.50 | F18: =广诚DHL运费!H6 -> 300.00 | G18: =广诚DHL运费!H7 -> 349.20 | H18: =广诚DHL运费!H8 -> 396.90 | I18: =广诚DHL运费!H9 -> 444.60 | J18: =广诚DHL运费!H10 -> 492.30 | K18: =广诚DHL运费!H11 -> 540.00 | L18: =广诚DHL运费!H12 -> 587.70 | M18: =广诚DHL运费!H13 -> 635.40 | N18: =广诚DHL运费!H14 -> 683.10 | O18: =广诚DHL运费!H15 -> 730.80 | P18: =广诚DHL运费!H16 -> 778.50 | Q18: =广诚DHL运费!H17 -> 826.20 | R18: =广诚DHL运费!H18 -> 873.90 | S18: =广诚DHL运费!H19 -> 921.60 | T18: =广诚DHL运费!H20 -> 969.30 | U18: =广诚DHL运费!H21 -> 1,017.00 | V18: =广诚DHL运费!H22 -> 1,064.70 | W18: =广诚DHL运费!H23 -> 1,109.70 | X18: =广诚DHL运费!H24 -> 1,154.70 | Y18: =广诚DHL运费!H25 -> 1,199.70 | Z18: =广诚DHL运费!H26 -> 1,244.70 | AA18: =广诚DHL运费!H27 -> 1,289.70 | AB18: =广诚DHL运费!H28 -> 1,334.70 | AC18: =广诚DHL运费!H29 -> 1,379.70 | AD18: =广诚DHL运费!H30 -> 1,424.70 | AE18: =广诚DHL运费!H31 -> 1,469.70 | AF18: =广诚DHL运费!H32 -> 1,514.70 | AG18: =广诚DHL运费!H33 -> 1,559.70 | AH18: =广诚DHL运费!H34 -> 1,604.70 | AI18: =广诚DHL运费!H35 -> 1,649.70 | AJ18: =广诚DHL运费!H36 -> 1,694.70 | AK18: =广诚DHL运费!H37 -> 1,739.70 | AL18: =广诚DHL运费!H38 -> 1,784.70 | AM18: =广诚DHL运费!H39 -> 1,829.70 | AN18: =广诚DHL运费!H40 -> 1,874.70 | AO18: =广诚DHL运费!H41 -> 1,919.70 | AP18: =广诚DHL运费!H42 -> 1,964.70 | AQ18: 1078.14 | AR18: 1094.8 | AS18: 1111.46 | AT18: 1128.12 | AU18: 1144.78 | AV18: 1161.44 | AW18: 1178.1 | AX18: 1194.76 | AY18: 1211.42 | AZ18: 1228.08 | BA18: 1244.74 | BB18: 1261.4 | BC18: 1278.06 | BD18: 1294.72 | BE18: 1311.38 | BF18: 1328.04 | BG18: 1344.7 | BH18: 1361.36 | BI18: 1378.02 | BJ18: 1394.68
A19: 墨西哥 | B19: 6 | C19: =广诚DHL运费!H3 -> 151.50 | D19: =广诚DHL运费!H4 -> 201.00 | E19: =广诚DHL运费!H5 -> 250.50 | F19: =广诚DHL运费!H6 -> 300.00 | G19: =广诚DHL运费!H7 -> 349.20 | H19: =广诚DHL运费!H8 -> 396.90 | I19: =广诚DHL运费!H9 -> 444.60 | J19: =广诚DHL运费!H10 -> 492.30 | K19: =广诚DHL运费!H11 -> 540.00 | L19: =广诚DHL运费!H12 -> 587.70 | M19: =广诚DHL运费!H13 -> 635.40 | N19: =广诚DHL运费!H14 -> 683.10 | O19: =广诚DHL运费!H15 -> 730.80 | P19: =广诚DHL运费!H16 -> 778.50 | Q19: =广诚DHL运费!H17 -> 826.20 | R19: =广诚DHL运费!H18 -> 873.90 | S19: =广诚DHL运费!H19 -> 921.60 | T19: =广诚DHL运费!H20 -> 969.30 | U19: =广诚DHL运费!H21 -> 1,017.00 | V19: =广诚DHL运费!H22 -> 1,064.70 | W19: =广诚DHL运费!H23 -> 1,109.70 | X19: =广诚DHL运费!H24 -> 1,154.70 | Y19: =广诚DHL运费!H25 -> 1,199.70 | Z19: =广诚DHL运费!H26 -> 1,244.70 | AA19: =广诚DHL运费!H27 -> 1,289.70 | AB19: =广诚DHL运费!H28 -> 1,334.70 | AC19: =广诚DHL运费!H29 -> 1,379.70 | AD19: =广诚DHL运费!H30 -> 1,424.70 | AE19: =广诚DHL运费!H31 -> 1,469.70 | AF19: =广诚DHL运费!H32 -> 1,514.70 | AG19: =广诚DHL运费!H33 -> 1,559.70 | AH19: =广诚DHL运费!H34 -> 1,604.70 | AI19: =广诚DHL运费!H35 -> 1,649.70 | AJ19: =广诚DHL运费!H36 -> 1,694.70 | AK19: =广诚DHL运费!H37 -> 1,739.70 | AL19: =广诚DHL运费!H38 -> 1,784.70 | AM19: =广诚DHL运费!H39 -> 1,829.70 | AN19: =广诚DHL运费!H40 -> 1,874.70 | AO19: =广诚DHL运费!H41 -> 1,919.70 | AP19: =广诚DHL运费!H42 -> 1,964.70 | AQ19: 1078.14 | AR19: 1094.8 | AS19: 1111.46 | AT19: 1128.12 | AU19: 1144.78 | AV19: 1161.44 | AW19: 1178.1 | AX19: 1194.76 | AY19: 1211.42 | AZ19: 1228.08 | BA19: 1244.74 | BB19: 1261.4 | BC19: 1278.06 | BD19: 1294.72 | BE19: 1311.38 | BF19: 1328.04 | BG19: 1344.7 | BH19: 1361.36 | BI19: 1378.02 | BJ19: 1394.68
A20: 美国 | B20: 6 | C20: =广诚DHL运费!H3 -> 151.50 | D20: =广诚DHL运费!H4 -> 201.00 | E20: =广诚DHL运费!H5 -> 250.50 | F20: =广诚DHL运费!H6 -> 300.00 | G20: =广诚DHL运费!H7 -> 349.20 | H20: =广诚DHL运费!H8 -> 396.90 | I20: =广诚DHL运费!H9 -> 444.60 | J20: =广诚DHL运费!H10 -> 492.30 | K20: =广诚DHL运费!H11 -> 540.00 | L20: =广诚DHL运费!H12 -> 587.70 | M20: =广诚DHL运费!H13 -> 635.40 | N20: =广诚DHL运费!H14 -> 683.10 | O20: =广诚DHL运费!H15 -> 730.80 | P20: =广诚DHL运费!H16 -> 778.50 | Q20: =广诚DHL运费!H17 -> 826.20 | R20: =广诚DHL运费!H18 -> 873.90 | S20: =广诚DHL运费!H19 -> 921.60 | T20: =广诚DHL运费!H20 -> 969.30 | U20: =广诚DHL运费!H21 -> 1,017.00 | V20: =广诚DHL运费!H22 -> 1,064.70 | W20: =广诚DHL运费!H23 -> 1,109.70 | X20: =广诚DHL运费!H24 -> 1,154.70 | Y20: =广诚DHL运费!H25 -> 1,199.70 | Z20: =广诚DHL运费!H26 -> 1,244.70 | AA20: =广诚DHL运费!H27 -> 1,289.70 | AB20: =广诚DHL运费!H28 -> 1,334.70 | AC20: =广诚DHL运费!H29 -> 1,379.70 | AD20: =广诚DHL运费!H30 -> 1,424.70 | AE20: =广诚DHL运费!H31 -> 1,469.70 | AF20: =广诚DHL运费!H32 -> 1,514.70 | AG20: =广诚DHL运费!H33 -> 1,559.70 | AH20: =广诚DHL运费!H34 -> 1,604.70 | AI20: =广诚DHL运费!H35 -> 1,649.70 | AJ20: =广诚DHL运费!H36 -> 1,694.70 | AK20: =广诚DHL运费!H37 -> 1,739.70 | AL20: =广诚DHL运费!H38 -> 1,784.70 | AM20: =广诚DHL运费!H39 -> 1,829.70 | AN20: =广诚DHL运费!H40 -> 1,874.70 | AO20: =广诚DHL运费!H41 -> 1,919.70 | AP20: =广诚DHL运费!H42 -> 1,964.70 | AQ20: 1078.14 | AR20: 1094.8 | AS20: 1111.46 | AT20: 1128.12 | AU20: 1144.78 | AV20: 1161.44 | AW20: 1178.1 | AX20: 1194.76 | AY20: 1211.42 | AZ20: 1228.08 | BA20: 1244.74 | BB20: 1261.4 | BC20: 1278.06 | BD20: 1294.72 | BE20: 1311.38 | BF20: 1328.04 | BG20: 1344.7 | BH20: 1361.36 | BI20: 1378.02 | BJ20: 1394.68
A21: 安道尔 | B21: 7 | C21: =广诚DHL运费!I3 -> 192.60 | D21: =广诚DHL运费!I4 -> 242.70 | E21: =广诚DHL运费!I5 -> 292.80 | F21: =广诚DHL运费!I6 -> 342.90 | G21: =广诚DHL运费!I7 -> 393.00 | H21: =广诚DHL运费!I8 -> 446.10 | I21: =广诚DHL运费!I9 -> 499.20 | J21: =广诚DHL运费!I10 -> 552.30 | K21: =广诚DHL运费!I11 -> 605.40 | L21: =广诚DHL运费!I12 -> 658.50 | M21: =广诚DHL运费!I13 -> 706.50 | N21: =广诚DHL运费!I14 -> 754.50 | O21: =广诚DHL运费!I15 -> 802.50 | P21: =广诚DHL运费!I16 -> 850.50 | Q21: =广诚DHL运费!I17 -> 898.50 | R21: =广诚DHL运费!I18 -> 946.50 | S21: =广诚DHL运费!I19 -> 994.50 | T21: =广诚DHL运费!I20 -> 1,042.50 | U21: =广诚DHL运费!I21 -> 1,090.50 | V21: =广诚DHL运费!I22 -> 1,138.50 | W21: =广诚DHL运费!I23 -> 1,181.10 | X21: =广诚DHL运费!I24 -> 1,223.70 | Y21: =广诚DHL运费!I25 -> 1,266.30 | Z21: =广诚DHL运费!I26 -> 1,308.90 | AA21: =广诚DHL运费!I27 -> 1,351.50 | AB21: =广诚DHL运费!I28 -> 1,394.10 | AC21: =广诚DHL运费!I29 -> 1,436.70 | AD21: =广诚DHL运费!I30 -> 1,479.30 | AE21: =广诚DHL运费!I31 -> 1,521.90 | AF21: =广诚DHL运费!I32 -> 1,564.50 | AG21: =广诚DHL运费!I33 -> 1,607.10 | AH21: =广诚DHL运费!I34 -> 1,649.70 | AI21: =广诚DHL运费!I35 -> 1,692.30 | AJ21: =广诚DHL运费!I36 -> 1,734.90 | AK21: =广诚DHL运费!I37 -> 1,777.50 | AL21: =广诚DHL运费!I38 -> 1,820.10 | AM21: =广诚DHL运费!I39 -> 1,862.70 | AN21: =广诚DHL运费!I40 -> 1,905.30 | AO21: =广诚DHL运费!I41 -> 1,947.90 | AP21: =广诚DHL运费!I42 -> 1,990.50 | AQ21: 968.25 | AR21: 988.05 | AS21: 1007.85 | AT21: 1027.65 | AU21: 1047.45 | AV21: 1067.25 | AW21: 1087.05 | AX21: 1106.85 | AY21: 1126.65 | AZ21: 1146.45 | BA21: 1166.25 | BB21: 1186.05 | BC21: 1205.85 | BD21: 1225.65 | BE21: 1245.45 | BF21: 1265.25 | BG21: 1285.05 | BH21: 1304.85 | BI21: 1324.65 | BJ21: 1344.45
A22: 奥地利 | B22: 7 | C22: =广诚DHL运费!I3 -> 192.60 | D22: =广诚DHL运费!I4 -> 242.70 | E22: =广诚DHL运费!I5 -> 292.80 | F22: =广诚DHL运费!I6 -> 342.90 | G22: =广诚DHL运费!I7 -> 393.00 | H22: =广诚DHL运费!I8 -> 446.10 | I22: =广诚DHL运费!I9 -> 499.20 | J22: =广诚DHL运费!I10 -> 552.30 | K22: =广诚DHL运费!I11 -> 605.40 | L22: =广诚DHL运费!I12 -> 658.50 | M22: =广诚DHL运费!I13 -> 706.50 | N22: =广诚DHL运费!I14 -> 754.50 | O22: =广诚DHL运费!I15 -> 802.50 | P22: =广诚DHL运费!I16 -> 850.50 | Q22: =广诚DHL运费!I17 -> 898.50 | R22: =广诚DHL运费!I18 -> 946.50 | S22: =广诚DHL运费!I19 -> 994.50 | T22: =广诚DHL运费!I20 -> 1,042.50 | U22: =广诚DHL运费!I21 -> 1,090.50 | V22: =广诚DHL运费!I22 -> 1,138.50 | W22: =广诚DHL运费!I23 -> 1,181.10 | X22: =广诚DHL运费!I24 -> 1,223.70 | Y22: =广诚DHL运费!I25 -> 1,266.30 | Z22: =广诚DHL运费!I26 -> 1,308.90 | AA22: =广诚DHL运费!I27 -> 1,351.50 | AB22: =广诚DHL运费!I28 -> 1,394.10 | AC22: =广诚DHL运费!I29 -> 1,436.70 | AD22: =广诚DHL运费!I30 -> 1,479.30 | AE22: =广诚DHL运费!I31 -> 1,521.90 | AF22: =广诚DHL运费!I32 -> 1,564.50 | AG22: =广诚DHL运费!I33 -> 1,607.10 | AH22: =广诚DHL运费!I34 -> 1,649.70 | AI22: =广诚DHL运费!I35 -> 1,692.30 | AJ22: =广诚DHL运费!I36 -> 1,734.90 | AK22: =广诚DHL运费!I37 -> 1,777.50 | AL22: =广诚DHL运费!I38 -> 1,820.10 | AM22: =广诚DHL运费!I39 -> 1,862.70 | AN22: =广诚DHL运费!I40 -> 1,905.30 | AO22: =广诚DHL运费!I41 -> 1,947.90 | AP22: =广诚DHL运费!I42 -> 1,990.50 | AQ22: 968.25 | AR22: 988.05 | AS22: 1007.85 | AT22: 1027.65 | AU22: 1047.45 | AV22: 1067.25 | AW22: 1087.05 | AX22: 1106.85 | AY22: 1126.65 | AZ22: 1146.45 | BA22: 1166.25 | BB22: 1186.05 | BC22: 1205.85 | BD22: 1225.65 | BE22: 1245.45 | BF22: 1265.25 | BG22: 1285.05 | BH22: 1304.85 | BI22: 1324.65 | BJ22: 1344.45
A23: 比利时 | B23: 7 | C23: =广诚DHL运费!I3 -> 192.60 | D23: =广诚DHL运费!I4 -> 242.70 | E23: =广诚DHL运费!I5 -> 292.80 | F23: =广诚DHL运费!I6 -> 342.90 | G23: =广诚DHL运费!I7 -> 393.00 | H23: =广诚DHL运费!I8 -> 446.10 | I23: =广诚DHL运费!I9 -> 499.20 | J23: =广诚DHL运费!I10 -> 552.30 | K23: =广诚DHL运费!I11 -> 605.40 | L23: =广诚DHL运费!I12 -> 658.50 | M23: =广诚DHL运费!I13 -> 706.50 | N23: =广诚DHL运费!I14 -> 754.50 | O23: =广诚DHL运费!I15 -> 802.50 | P23: =广诚DHL运费!I16 -> 850.50 | Q23: =广诚DHL运费!I17 -> 898.50 | R23: =广诚DHL运费!I18 -> 946.50 | S23: =广诚DHL运费!I19 -> 994.50 | T23: =广诚DHL运费!I20 -> 1,042.50 | U23: =广诚DHL运费!I21 -> 1,090.50 | V23: =广诚DHL运费!I22 -> 1,138.50 | W23: =广诚DHL运费!I23 -> 1,181.10 | X23: =广诚DHL运费!I24 -> 1,223.70 | Y23: =广诚DHL运费!I25 -> 1,266.30 | Z23: =广诚DHL运费!I26 -> 1,308.90 | AA23: =广诚DHL运费!I27 -> 1,351.50 | AB23: =广诚DHL运费!I28 -> 1,394.10 | AC23: =广诚DHL运费!I29 -> 1,436.70 | AD23: =广诚DHL运费!I30 -> 1,479.30 | AE23: =广诚DHL运费!I31 -> 1,521.90 | AF23: =广诚DHL运费!I32 -> 1,564.50 | AG23: =广诚DHL运费!I33 -> 1,607.10 | AH23: =广诚DHL运费!I34 -> 1,649.70 | AI23: =广诚DHL运费!I35 -> 1,692.30 | AJ23: =广诚DHL运费!I36 -> 1,734.90 | AK23: =广诚DHL运费!I37 -> 1,777.50 | AL23: =广诚DHL运费!I38 -> 1,820.10 | AM23: =广诚DHL运费!I39 -> 1,862.70 | AN23: =广诚DHL运费!I40 -> 1,905.30 | AO23: =广诚DHL运费!I41 -> 1,947.90 | AP23: =广诚DHL运费!I42 -> 1,990.50 | AQ23: 968.25 | AR23: 988.05 | AS23: 1007.85 | AT23: 1027.65 | AU23: 1047.45 | AV23: 1067.25 | AW23: 1087.05 | AX23: 1106.85 | AY23: 1126.65 | AZ23: 1146.45 | BA23: 1166.25 | BB23: 1186.05 | BC23: 1205.85 | BD23: 1225.65 | BE23: 1245.45 | BF23: 1265.25 | BG23: 1285.05 | BH23: 1304.85 | BI23: 1324.65 | BJ23: 1344.45
A24: 保加利亚 | B24: 7 | C24: =广诚DHL运费!I3 -> 192.60 | D24: =广诚DHL运费!I4 -> 242.70 | E24: =广诚DHL运费!I5 -> 292.80 | F24: =广诚DHL运费!I6 -> 342.90 | G24: =广诚DHL运费!I7 -> 393.00 | H24: =广诚DHL运费!I8 -> 446.10 | I24: =广诚DHL运费!I9 -> 499.20 | J24: =广诚DHL运费!I10 -> 552.30 | K24: =广诚DHL运费!I11 -> 605.40 | L24: =广诚DHL运费!I12 -> 658.50 | M24: =广诚DHL运费!I13 -> 706.50 | N24: =广诚DHL运费!I14 -> 754.50 | O24: =广诚DHL运费!I15 -> 802.50 | P24: =广诚DHL运费!I16 -> 850.50 | Q24: =广诚DHL运费!I17 -> 898.50 | R24: =广诚DHL运费!I18 -> 946.50 | S24: =广诚DHL运费!I19 -> 994.50 | T24: =广诚DHL运费!I20 -> 1,042.50 | U24: =广诚DHL运费!I21 -> 1,090.50 | V24: =广诚DHL运费!I22 -> 1,138.50 | W24: =广诚DHL运费!I23 -> 1,181.10 | X24: =广诚DHL运费!I24 -> 1,223.70 | Y24: =广诚DHL运费!I25 -> 1,266.30 | Z24: =广诚DHL运费!I26 -> 1,308.90 | AA24: =广诚DHL运费!I27 -> 1,351.50 | AB24: =广诚DHL运费!I28 -> 1,394.10 | AC24: =广诚DHL运费!I29 -> 1,436.70 | AD24: =广诚DHL运费!I30 -> 1,479.30 | AE24: =广诚DHL运费!I31 -> 1,521.90 | AF24: =广诚DHL运费!I32 -> 1,564.50 | AG24: =广诚DHL运费!I33 -> 1,607.10 | AH24: =广诚DHL运费!I34 -> 1,649.70 | AI24: =广诚DHL运费!I35 -> 1,692.30 | AJ24: =广诚DHL运费!I36 -> 1,734.90 | AK24: =广诚DHL运费!I37 -> 1,777.50 | AL24: =广诚DHL运费!I38 -> 1,820.10 | AM24: =广诚DHL运费!I39 -> 1,862.70 | AN24: =广诚DHL运费!I40 -> 1,905.30 | AO24: =广诚DHL运费!I41 -> 1,947.90 | AP24: =广诚DHL运费!I42 -> 1,990.50 | AQ24: 968.25 | AR24: 988.05 | AS24: 1007.85 | AT24: 1027.65 | AU24: 1047.45 | AV24: 1067.25 | AW24: 1087.05 | AX24: 1106.85 | AY24: 1126.65 | AZ24: 1146.45 | BA24: 1166.25 | BB24: 1186.05 | BC24: 1205.85 | BD24: 1225.65 | BE24: 1245.45 | BF24: 1265.25 | BG24: 1285.05 | BH24: 1304.85 | BI24: 1324.65 | BJ24: 1344.45
A25: 瑞士 | B25: 7 | C25: =广诚DHL运费!I3 -> 192.60 | D25: =广诚DHL运费!I4 -> 242.70 | E25: =广诚DHL运费!I5 -> 292.80 | F25: =广诚DHL运费!I6 -> 342.90 | G25: =广诚DHL运费!I7 -> 393.00 | H25: =广诚DHL运费!I8 -> 446.10 | I25: =广诚DHL运费!I9 -> 499.20 | J25: =广诚DHL运费!I10 -> 552.30 | K25: =广诚DHL运费!I11 -> 605.40 | L25: =广诚DHL运费!I12 -> 658.50 | M25: =广诚DHL运费!I13 -> 706.50 | N25: =广诚DHL运费!I14 -> 754.50 | O25: =广诚DHL运费!I15 -> 802.50 | P25: =广诚DHL运费!I16 -> 850.50 | Q25: =广诚DHL运费!I17 -> 898.50 | R25: =广诚DHL运费!I18 -> 946.50 | S25: =广诚DHL运费!I19 -> 994.50 | T25: =广诚DHL运费!I20 -> 1,042.50 | U25: =广诚DHL运费!I21 -> 1,090.50 | V25: =广诚DHL运费!I22 -> 1,138.50 | W25: =广诚DHL运费!I23 -> 1,181.10 | X25: =广诚DHL运费!I24 -> 1,223.70 | Y25: =广诚DHL运费!I25 -> 1,266.30 | Z25: =广诚DHL运费!I26 -> 1,308.90 | AA25: =广诚DHL运费!I27 -> 1,351.50 | AB25: =广诚DHL运费!I28 -> 1,394.10 | AC25: =广诚DHL运费!I29 -> 1,436.70 | AD25: =广诚DHL运费!I30 -> 1,479.30 | AE25: =广诚DHL运费!I31 -> 1,521.90 | AF25: =广诚DHL运费!I32 -> 1,564.50 | AG25: =广诚DHL运费!I33 -> 1,607.10 | AH25: =广诚DHL运费!I34 -> 1,649.70 | AI25: =广诚DHL运费!I35 -> 1,692.30 | AJ25: =广诚DHL运费!I36 -> 1,734.90 | AK25: =广诚DHL运费!I37 -> 1,777.50 | AL25: =广诚DHL运费!I38 -> 1,820.10 | AM25: =广诚DHL运费!I39 -> 1,862.70 | AN25: =广诚DHL运费!I40 -> 1,905.30 | AO25: =广诚DHL运费!I41 -> 1,947.90 | AP25: =广诚DHL运费!I42 -> 1,990.50 | AQ25: 968.25 | AR25: 988.05 | AS25: 1007.85 | AT25: 1027.65 | AU25: 1047.45 | AV25: 1067.25 | AW25: 1087.05 | AX25: 1106.85 | AY25: 1126.65 | AZ25: 1146.45 | BA25: 1166.25 | BB25: 1186.05 | BC25: 1205.85 | BD25: 1225.65 | BE25: 1245.45 | BF25: 1265.25 | BG25: 1285.05 | BH25: 1304.85 | BI25: 1324.65 | BJ25: 1344.45
A26: 塞浦路斯 | B26: 7 | C26: =广诚DHL运费!I3 -> 192.60 | D26: =广诚DHL运费!I4 -> 242.70 | E26: =广诚DHL运费!I5 -> 292.80 | F26: =广诚DHL运费!I6 -> 342.90 | G26: =广诚DHL运费!I7 -> 393.00 | H26: =广诚DHL运费!I8 -> 446.10 | I26: =广诚DHL运费!I9 -> 499.20 | J26: =广诚DHL运费!I10 -> 552.30 | K26: =广诚DHL运费!I11 -> 605.40 | L26: =广诚DHL运费!I12 -> 658.50 | M26: =广诚DHL运费!I13 -> 706.50 | N26: =广诚DHL运费!I14 -> 754.50 | O26: =广诚DHL运费!I15 -> 802.50 | P26: =广诚DHL运费!I16 -> 850.50 | Q26: =广诚DHL运费!I17 -> 898.50 | R26: =广诚DHL运费!I18 -> 946.50 | S26: =广诚DHL运费!I19 -> 994.50 | T26: =广诚DHL运费!I20 -> 1,042.50 | U26: =广诚DHL运费!I21 -> 1,090.50 | V26: =广诚DHL运费!I22 -> 1,138.50 | W26: =广诚DHL运费!I23 -> 1,181.10 | X26: =广诚DHL运费!I24 -> 1,223.70 | Y26: =广诚DHL运费!I25 -> 1,266.30 | Z26: =广诚DHL运费!I26 -> 1,308.90 | AA26: =广诚DHL运费!I27 -> 1,351.50 | AB26: =广诚DHL运费!I28 -> 1,394.10 | AC26: =广诚DHL运费!I29 -> 1,436.70 | AD26: =广诚DHL运费!I30 -> 1,479.30 | AE26: =广诚DHL运费!I31 -> 1,521.90 | AF26: =广诚DHL运费!I32 -> 1,564.50 | AG26: =广诚DHL运费!I33 -> 1,607.10 | AH26: =广诚DHL运费!I34 -> 1,649.70 | AI26: =广诚DHL运费!I35 -> 1,692.30 | AJ26: =广诚DHL运费!I36 -> 1,734.90 | AK26: =广诚DHL运费!I37 -> 1,777.50 | AL26: =广诚DHL运费!I38 -> 1,820.10 | AM26: =广诚DHL运费!I39 -> 1,862.70 | AN26: =广诚DHL运费!I40 -> 1,905.30 | AO26: =广诚DHL运费!I41 -> 1,947.90 | AP26: =广诚DHL运费!I42 -> 1,990.50 | AQ26: 968.25 | AR26: 988.05 | AS26: 1007.85 | AT26: 1027.65 | AU26: 1047.45 | AV26: 1067.25 | AW26: 1087.05 | AX26: 1106.85 | AY26: 1126.65 | AZ26: 1146.45 | BA26: 1166.25 | BB26: 1186.05 | BC26: 1205.85 | BD26: 1225.65 | BE26: 1245.45 | BF26: 1265.25 | BG26: 1285.05 | BH26: 1304.85 | BI26: 1324.65 | BJ26: 1344.45
A27: 捷克共和国 | B27: 7 | C27: =广诚DHL运费!I3 -> 192.60 | D27: =广诚DHL运费!I4 -> 242.70 | E27: =广诚DHL运费!I5 -> 292.80 | F27: =广诚DHL运费!I6 -> 342.90 | G27: =广诚DHL运费!I7 -> 393.00 | H27: =广诚DHL运费!I8 -> 446.10 | I27: =广诚DHL运费!I9 -> 499.20 | J27: =广诚DHL运费!I10 -> 552.30 | K27: =广诚DHL运费!I11 -> 605.40 | L27: =广诚DHL运费!I12 -> 658.50 | M27: =广诚DHL运费!I13 -> 706.50 | N27: =广诚DHL运费!I14 -> 754.50 | O27: =广诚DHL运费!I15 -> 802.50 | P27: =广诚DHL运费!I16 -> 850.50 | Q27: =广诚DHL运费!I17 -> 898.50 | R27: =广诚DHL运费!I18 -> 946.50 | S27: =广诚DHL运费!I19 -> 994.50 | T27: =广诚DHL运费!I20 -> 1,042.50 | U27: =广诚DHL运费!I21 -> 1,090.50 | V27: =广诚DHL运费!I22 -> 1,138.50 | W27: =广诚DHL运费!I23 -> 1,181.10 | X27: =广诚DHL运费!I24 -> 1,223.70 | Y27: =广诚DHL运费!I25 -> 1,266.30 | Z27: =广诚DHL运费!I26 -> 1,308.90 | AA27: =广诚DHL运费!I27 -> 1,351.50 | AB27: =广诚DHL运费!I28 -> 1,394.10 | AC27: =广诚DHL运费!I29 -> 1,436.70 | AD27: =广诚DHL运费!I30 -> 1,479.30 | AE27: =广诚DHL运费!I31 -> 1,521.90 | AF27: =广诚DHL运费!I32 -> 1,564.50 | AG27: =广诚DHL运费!I33 -> 1,607.10 | AH27: =广诚DHL运费!I34 -> 1,649.70 | AI27: =广诚DHL运费!I35 -> 1,692.30 | AJ27: =广诚DHL运费!I36 -> 1,734.90 | AK27: =广诚DHL运费!I37 -> 1,777.50 | AL27: =广诚DHL运费!I38 -> 1,820.10 | AM27: =广诚DHL运费!I39 -> 1,862.70 | AN27: =广诚DHL运费!I40 -> 1,905.30 | AO27: =广诚DHL运费!I41 -> 1,947.90 | AP27: =广诚DHL运费!I42 -> 1,990.50 | AQ27: 968.25 | AR27: 988.05 | AS27: 1007.85 | AT27: 1027.65 | AU27: 1047.45 | AV27: 1067.25 | AW27: 1087.05 | AX27: 1106.85 | AY27: 1126.65 | AZ27: 1146.45 | BA27: 1166.25 | BB27: 1186.05 | BC27: 1205.85 | BD27: 1225.65 | BE27: 1245.45 | BF27: 1265.25 | BG27: 1285.05 | BH27: 1304.85 | BI27: 1324.65 | BJ27: 1344.45
A28: 德国 | B28: 7 | C28: =广诚DHL运费!I3 -> 192.60 | D28: =广诚DHL运费!I4 -> 242.70 | E28: =广诚DHL运费!I5 -> 292.80 | F28: =广诚DHL运费!I6 -> 342.90 | G28: =广诚DHL运费!I7 -> 393.00 | H28: =广诚DHL运费!I8 -> 446.10 | I28: =广诚DHL运费!I9 -> 499.20 | J28: =广诚DHL运费!I10 -> 552.30 | K28: =广诚DHL运费!I11 -> 605.40 | L28: =广诚DHL运费!I12 -> 658.50 | M28: =广诚DHL运费!I13 -> 706.50 | N28: =广诚DHL运费!I14 -> 754.50 | O28: =广诚DHL运费!I15 -> 802.50 | P28: =广诚DHL运费!I16 -> 850.50 | Q28: =广诚DHL运费!I17 -> 898.50 | R28: =广诚DHL运费!I18 -> 946.50 | S28: =广诚DHL运费!I19 -> 994.50 | T28: =广诚DHL运费!I20 -> 1,042.50 | U28: =广诚DHL运费!I21 -> 1,090.50 | V28: =广诚DHL运费!I22 -> 1,138.50 | W28: =广诚DHL运费!I23 -> 1,181.10 | X28: =广诚DHL运费!I24 -> 1,223.70 | Y28: =广诚DHL运费!I25 -> 1,266.30 | Z28: =广诚DHL运费!I26 -> 1,308.90 | AA28: =广诚DHL运费!I27 -> 1,351.50 | AB28: =广诚DHL运费!I28 -> 1,394.10 | AC28: =广诚DHL运费!I29 -> 1,436.70 | AD28: =广诚DHL运费!I30 -> 1,479.30 | AE28: =广诚DHL运费!I31 -> 1,521.90 | AF28: =广诚DHL运费!I32 -> 1,564.50 | AG28: =广诚DHL运费!I33 -> 1,607.10 | AH28: =广诚DHL运费!I34 -> 1,649.70 | AI28: =广诚DHL运费!I35 -> 1,692.30 | AJ28: =广诚DHL运费!I36 -> 1,734.90 | AK28: =广诚DHL运费!I37 -> 1,777.50 | AL28: =广诚DHL运费!I38 -> 1,820.10 | AM28: =广诚DHL运费!I39 -> 1,862.70 | AN28: =广诚DHL运费!I40 -> 1,905.30 | AO28: =广诚DHL运费!I41 -> 1,947.90 | AP28: =广诚DHL运费!I42 -> 1,990.50 | AQ28: 968.25 | AR28: 988.05 | AS28: 1007.85 | AT28: 1027.65 | AU28: 1047.45 | AV28: 1067.25 | AW28: 1087.05 | AX28: 1106.85 | AY28: 1126.65 | AZ28: 1146.45 | BA28: 1166.25 | BB28: 1186.05 | BC28: 1205.85 | BD28: 1225.65 | BE28: 1245.45 | BF28: 1265.25 | BG28: 1285.05 | BH28: 1304.85 | BI28: 1324.65 | BJ28: 1344.45
A29: 丹麦 | B29: 7 | C29: =广诚DHL运费!I3 -> 192.60 | D29: =广诚DHL运费!I4 -> 242.70 | E29: =广诚DHL运费!I5 -> 292.80 | F29: =广诚DHL运费!I6 -> 342.90 | G29: =广诚DHL运费!I7 -> 393.00 | H29: =广诚DHL运费!I8 -> 446.10 | I29: =广诚DHL运费!I9 -> 499.20 | J29: =广诚DHL运费!I10 -> 552.30 | K29: =广诚DHL运费!I11 -> 605.40 | L29: =广诚DHL运费!I12 -> 658.50 | M29: =广诚DHL运费!I13 -> 706.50 | N29: =广诚DHL运费!I14 -> 754.50 | O29: =广诚DHL运费!I15 -> 802.50 | P29: =广诚DHL运费!I16 -> 850.50 | Q29: =广诚DHL运费!I17 -> 898.50 | R29: =广诚DHL运费!I18 -> 946.50 | S29: =广诚DHL运费!I19 -> 994.50 | T29: =广诚DHL运费!I20 -> 1,042.50 | U29: =广诚DHL运费!I21 -> 1,090.50 | V29: =广诚DHL运费!I22 -> 1,138.50 | W29: =广诚DHL运费!I23 -> 1,181.10 | X29: =广诚DHL运费!I24 -> 1,223.70 | Y29: =广诚DHL运费!I25 -> 1,266.30 | Z29: =广诚DHL运费!I26 -> 1,308.90 | AA29: =广诚DHL运费!I27 -> 1,351.50 | AB29: =广诚DHL运费!I28 -> 1,394.10 | AC29: =广诚DHL运费!I29 -> 1,436.70 | AD29: =广诚DHL运费!I30 -> 1,479.30 | AE29: =广诚DHL运费!I31 -> 1,521.90 | AF29: =广诚DHL运费!I32 -> 1,564.50 | AG29: =广诚DHL运费!I33 -> 1,607.10 | AH29: =广诚DHL运费!I34 -> 1,649.70 | AI29: =广诚DHL运费!I35 -> 1,692.30 | AJ29: =广诚DHL运费!I36 -> 1,734.90 | AK29: =广诚DHL运费!I37 -> 1,777.50 | AL29: =广诚DHL运费!I38 -> 1,820.10 | AM29: =广诚DHL运费!I39 -> 1,862.70 | AN29: =广诚DHL运费!I40 -> 1,905.30 | AO29: =广诚DHL运费!I41 -> 1,947.90 | AP29: =广诚DHL运费!I42 -> 1,990.50 | AQ29: 968.25 | AR29: 988.05 | AS29: 1007.85 | AT29: 1027.65 | AU29: 1047.45 | AV29: 1067.25 | AW29: 1087.05 | AX29: 1106.85 | AY29: 1126.65 | AZ29: 1146.45 | BA29: 1166.25 | BB29: 1186.05 | BC29: 1205.85 | BD29: 1225.65 | BE29: 1245.45 | BF29: 1265.25 | BG29: 1285.05 | BH29: 1304.85 | BI29: 1324.65 | BJ29: 1344.45
A30: 爱沙尼亚 | B30: 7 | C30: =广诚DHL运费!I3 -> 192.60 | D30: =广诚DHL运费!I4 -> 242.70 | E30: =广诚DHL运费!I5 -> 292.80 | F30: =广诚DHL运费!I6 -> 342.90 | G30: =广诚DHL运费!I7 -> 393.00 | H30: =广诚DHL运费!I8 -> 446.10 | I30: =广诚DHL运费!I9 -> 499.20 | J30: =广诚DHL运费!I10 -> 552.30 | K30: =广诚DHL运费!I11 -> 605.40 | L30: =广诚DHL运费!I12 -> 658.50 | M30: =广诚DHL运费!I13 -> 706.50 | N30: =广诚DHL运费!I14 -> 754.50 | O30: =广诚DHL运费!I15 -> 802.50 | P30: =广诚DHL运费!I16 -> 850.50 | Q30: =广诚DHL运费!I17 -> 898.50 | R30: =广诚DHL运费!I18 -> 946.50 | S30: =广诚DHL运费!I19 -> 994.50 | T30: =广诚DHL运费!I20 -> 1,042.50 | U30: =广诚DHL运费!I21 -> 1,090.50 | V30: =广诚DHL运费!I22 -> 1,138.50 | W30: =广诚DHL运费!I23 -> 1,181.10 | X30: =广诚DHL运费!I24 -> 1,223.70 | Y30: =广诚DHL运费!I25 -> 1,266.30 | Z30: =广诚DHL运费!I26 -> 1,308.90 | AA30: =广诚DHL运费!I27 -> 1,351.50 | AB30: =广诚DHL运费!I28 -> 1,394.10 | AC30: =广诚DHL运费!I29 -> 1,436.70 | AD30: =广诚DHL运费!I30 -> 1,479.30 | AE30: =广诚DHL运费!I31 -> 1,521.90 | AF30: =广诚DHL运费!I32 -> 1,564.50 | AG30: =广诚DHL运费!I33 -> 1,607.10 | AH30: =广诚DHL运费!I34 -> 1,649.70 | AI30: =广诚DHL运费!I35 -> 1,692.30 | AJ30: =广诚DHL运费!I36 -> 1,734.90 | AK30: =广诚DHL运费!I37 -> 1,777.50 | AL30: =广诚DHL运费!I38 -> 1,820.10 | AM30: =广诚DHL运费!I39 -> 1,862.70 | AN30: =广诚DHL运费!I40 -> 1,905.30 | AO30: =广诚DHL运费!I41 -> 1,947.90 | AP30: =广诚DHL运费!I42 -> 1,990.50 | AQ30: 968.25 | AR30: 988.05 | AS30: 1007.85 | AT30: 1027.65 | AU30: 1047.45 | AV30: 1067.25 | AW30: 1087.05 | AX30: 1106.85 | AY30: 1126.65 | AZ30: 1146.45 | BA30: 1166.25 | BB30: 1186.05 | BC30: 1205.85 | BD30: 1225.65 | BE30: 1245.45 | BF30: 1265.25 | BG30: 1285.05 | BH30: 1304.85 | BI30: 1324.65 | BJ30: 1344.45
A31: 西班牙 | B31: 7 | C31: =广诚DHL运费!I3 -> 192.60 | D31: =广诚DHL运费!I4 -> 242.70 | E31: =广诚DHL运费!I5 -> 292.80 | F31: =广诚DHL运费!I6 -> 342.90 | G31: =广诚DHL运费!I7 -> 393.00 | H31: =广诚DHL运费!I8 -> 446.10 | I31: =广诚DHL运费!I9 -> 499.20 | J31: =广诚DHL运费!I10 -> 552.30 | K31: =广诚DHL运费!I11 -> 605.40 | L31: =广诚DHL运费!I12 -> 658.50 | M31: =广诚DHL运费!I13 -> 706.50 | N31: =广诚DHL运费!I14 -> 754.50 | O31: =广诚DHL运费!I15 -> 802.50 | P31: =广诚DHL运费!I16 -> 850.50 | Q31: =广诚DHL运费!I17 -> 898.50 | R31: =广诚DHL运费!I18 -> 946.50 | S31: =广诚DHL运费!I19 -> 994.50 | T31: =广诚DHL运费!I20 -> 1,042.50 | U31: =广诚DHL运费!I21 -> 1,090.50 | V31: =广诚DHL运费!I22 -> 1,138.50 | W31: =广诚DHL运费!I23 -> 1,181.10 | X31: =广诚DHL运费!I24 -> 1,223.70 | Y31: =广诚DHL运费!I25 -> 1,266.30 | Z31: =广诚DHL运费!I26 -> 1,308.90 | AA31: =广诚DHL运费!I27 -> 1,351.50 | AB31: =广诚DHL运费!I28 -> 1,394.10 | AC31: =广诚DHL运费!I29 -> 1,436.70 | AD31: =广诚DHL运费!I30 -> 1,479.30 | AE31: =广诚DHL运费!I31 -> 1,521.90 | AF31: =广诚DHL运费!I32 -> 1,564.50 | AG31: =广诚DHL运费!I33 -> 1,607.10 | AH31: =广诚DHL运费!I34 -> 1,649.70 | AI31: =广诚DHL运费!I35 -> 1,692.30 | AJ31: =广诚DHL运费!I36 -> 1,734.90 | AK31: =广诚DHL运费!I37 -> 1,777.50 | AL31: =广诚DHL运费!I38 -> 1,820.10 | AM31: =广诚DHL运费!I39 -> 1,862.70 | AN31: =广诚DHL运费!I40 -> 1,905.30 | AO31: =广诚DHL运费!I41 -> 1,947.90 | AP31: =广诚DHL运费!I42 -> 1,990.50 | AQ31: 968.25 | AR31: 988.05 | AS31: 1007.85 | AT31: 1027.65 | AU31: 1047.45 | AV31: 1067.25 | AW31: 1087.05 | AX31: 1106.85 | AY31: 1126.65 | AZ31: 1146.45 | BA31: 1166.25 | BB31: 1186.05 | BC31: 1205.85 | BD31: 1225.65 | BE31: 1245.45 | BF31: 1265.25 | BG31: 1285.05 | BH31: 1304.85 | BI31: 1324.65 | BJ31: 1344.45
A32: 芬兰 | B32: 7 | C32: =广诚DHL运费!I3 -> 192.60 | D32: =广诚DHL运费!I4 -> 242.70 | E32: =广诚DHL运费!I5 -> 292.80 | F32: =广诚DHL运费!I6 -> 342.90 | G32: =广诚DHL运费!I7 -> 393.00 | H32: =广诚DHL运费!I8 -> 446.10 | I32: =广诚DHL运费!I9 -> 499.20 | J32: =广诚DHL运费!I10 -> 552.30 | K32: =广诚DHL运费!I11 -> 605.40 | L32: =广诚DHL运费!I12 -> 658.50 | M32: =广诚DHL运费!I13 -> 706.50 | N32: =广诚DHL运费!I14 -> 754.50 | O32: =广诚DHL运费!I15 -> 802.50 | P32: =广诚DHL运费!I16 -> 850.50 | Q32: =广诚DHL运费!I17 -> 898.50 | R32: =广诚DHL运费!I18 -> 946.50 | S32: =广诚DHL运费!I19 -> 994.50 | T32: =广诚DHL运费!I20 -> 1,042.50 | U32: =广诚DHL运费!I21 -> 1,090.50 | V32: =广诚DHL运费!I22 -> 1,138.50 | W32: =广诚DHL运费!I23 -> 1,181.10 | X32: =广诚DHL运费!I24 -> 1,223.70 | Y32: =广诚DHL运费!I25 -> 1,266.30 | Z32: =广诚DHL运费!I26 -> 1,308.90 | AA32: =广诚DHL运费!I27 -> 1,351.50 | AB32: =广诚DHL运费!I28 -> 1,394.10 | AC32: =广诚DHL运费!I29 -> 1,436.70 | AD32: =广诚DHL运费!I30 -> 1,479.30 | AE32: =广诚DHL运费!I31 -> 1,521.90 | AF32: =广诚DHL运费!I32 -> 1,564.50 | AG32: =广诚DHL运费!I33 -> 1,607.10 | AH32: =广诚DHL运费!I34 -> 1,649.70 | AI32: =广诚DHL运费!I35 -> 1,692.30 | AJ32: =广诚DHL运费!I36 -> 1,734.90 | AK32: =广诚DHL运费!I37 -> 1,777.50 | AL32: =广诚DHL运费!I38 -> 1,820.10 | AM32: =广诚DHL运费!I39 -> 1,862.70 | AN32: =广诚DHL运费!I40 -> 1,905.30 | AO32: =广诚DHL运费!I41 -> 1,947.90 | AP32: =广诚DHL运费!I42 -> 1,990.50 | AQ32: 968.25 | AR32: 988.05 | AS32: 1007.85 | AT32: 1027.65 | AU32: 1047.45 | AV32: 1067.25 | AW32: 1087.05 | AX32: 1106.85 | AY32: 1126.65 | AZ32: 1146.45 | BA32: 1166.25 | BB32: 1186.05 | BC32: 1205.85 | BD32: 1225.65 | BE32: 1245.45 | BF32: 1265.25 | BG32: 1285.05 | BH32: 1304.85 | BI32: 1324.65 | BJ32: 1344.45
A33: 法国 | B33: 7 | C33: =广诚DHL运费!I3 -> 192.60 | D33: =广诚DHL运费!I4 -> 242.70 | E33: =广诚DHL运费!I5 -> 292.80 | F33: =广诚DHL运费!I6 -> 342.90 | G33: =广诚DHL运费!I7 -> 393.00 | H33: =广诚DHL运费!I8 -> 446.10 | I33: =广诚DHL运费!I9 -> 499.20 | J33: =广诚DHL运费!I10 -> 552.30 | K33: =广诚DHL运费!I11 -> 605.40 | L33: =广诚DHL运费!I12 -> 658.50 | M33: =广诚DHL运费!I13 -> 706.50 | N33: =广诚DHL运费!I14 -> 754.50 | O33: =广诚DHL运费!I15 -> 802.50 | P33: =广诚DHL运费!I16 -> 850.50 | Q33: =广诚DHL运费!I17 -> 898.50 | R33: =广诚DHL运费!I18 -> 946.50 | S33: =广诚DHL运费!I19 -> 994.50 | T33: =广诚DHL运费!I20 -> 1,042.50 | U33: =广诚DHL运费!I21 -> 1,090.50 | V33: =广诚DHL运费!I22 -> 1,138.50 | W33: =广诚DHL运费!I23 -> 1,181.10 | X33: =广诚DHL运费!I24 -> 1,223.70 | Y33: =广诚DHL运费!I25 -> 1,266.30 | Z33: =广诚DHL运费!I26 -> 1,308.90 | AA33: =广诚DHL运费!I27 -> 1,351.50 | AB33: =广诚DHL运费!I28 -> 1,394.10 | AC33: =广诚DHL运费!I29 -> 1,436.70 | AD33: =广诚DHL运费!I30 -> 1,479.30 | AE33: =广诚DHL运费!I31 -> 1,521.90 | AF33: =广诚DHL运费!I32 -> 1,564.50 | AG33: =广诚DHL运费!I33 -> 1,607.10 | AH33: =广诚DHL运费!I34 -> 1,649.70 | AI33: =广诚DHL运费!I35 -> 1,692.30 | AJ33: =广诚DHL运费!I36 -> 1,734.90 | AK33: =广诚DHL运费!I37 -> 1,777.50 | AL33: =广诚DHL运费!I38 -> 1,820.10 | AM33: =广诚DHL运费!I39 -> 1,862.70 | AN33: =广诚DHL运费!I40 -> 1,905.30 | AO33: =广诚DHL运费!I41 -> 1,947.90 | AP33: =广诚DHL运费!I42 -> 1,990.50 | AQ33: 968.25 | AR33: 988.05 | AS33: 1007.85 | AT33: 1027.65 | AU33: 1047.45 | AV33: 1067.25 | AW33: 1087.05 | AX33: 1106.85 | AY33: 1126.65 | AZ33: 1146.45 | BA33: 1166.25 | BB33: 1186.05 | BC33: 1205.85 | BD33: 1225.65 | BE33: 1245.45 | BF33: 1265.25 | BG33: 1285.05 | BH33: 1304.85 | BI33: 1324.65 | BJ33: 1344.45
A34: 英国 | B34: 7 | C34: =广诚DHL运费!I3 -> 192.60 | D34: =广诚DHL运费!I4 -> 242.70 | E34: =广诚DHL运费!I5 -> 292.80 | F34: =广诚DHL运费!I6 -> 342.90 | G34: =广诚DHL运费!I7 -> 393.00 | H34: =广诚DHL运费!I8 -> 446.10 | I34: =广诚DHL运费!I9 -> 499.20 | J34: =广诚DHL运费!I10 -> 552.30 | K34: =广诚DHL运费!I11 -> 605.40 | L34: =广诚DHL运费!I12 -> 658.50 | M34: =广诚DHL运费!I13 -> 706.50 | N34: =广诚DHL运费!I14 -> 754.50 | O34: =广诚DHL运费!I15 -> 802.50 | P34: =广诚DHL运费!I16 -> 850.50 | Q34: =广诚DHL运费!I17 -> 898.50 | R34: =广诚DHL运费!I18 -> 946.50 | S34: =广诚DHL运费!I19 -> 994.50 | T34: =广诚DHL运费!I20 -> 1,042.50 | U34: =广诚DHL运费!I21 -> 1,090.50 | V34: =广诚DHL运费!I22 -> 1,138.50 | W34: =广诚DHL运费!I23 -> 1,181.10 | X34: =广诚DHL运费!I24 -> 1,223.70 | Y34: =广诚DHL运费!I25 -> 1,266.30 | Z34: =广诚DHL运费!I26 -> 1,308.90 | AA34: =广诚DHL运费!I27 -> 1,351.50 | AB34: =广诚DHL运费!I28 -> 1,394.10 | AC34: =广诚DHL运费!I29 -> 1,436.70 | AD34: =广诚DHL运费!I30 -> 1,479.30 | AE34: =广诚DHL运费!I31 -> 1,521.90 | AF34: =广诚DHL运费!I32 -> 1,564.50 | AG34: =广诚DHL运费!I33 -> 1,607.10 | AH34: =广诚DHL运费!I34 -> 1,649.70 | AI34: =广诚DHL运费!I35 -> 1,692.30 | AJ34: =广诚DHL运费!I36 -> 1,734.90 | AK34: =广诚DHL运费!I37 -> 1,777.50 | AL34: =广诚DHL运费!I38 -> 1,820.10 | AM34: =广诚DHL运费!I39 -> 1,862.70 | AN34: =广诚DHL运费!I40 -> 1,905.30 | AO34: =广诚DHL运费!I41 -> 1,947.90 | AP34: =广诚DHL运费!I42 -> 1,990.50 | AQ34: 968.25 | AR34: 988.05 | AS34: 1007.85 | AT34: 1027.65 | AU34: 1047.45 | AV34: 1067.25 | AW34: 1087.05 | AX34: 1106.85 | AY34: 1126.65 | AZ34: 1146.45 | BA34: 1166.25 | BB34: 1186.05 | BC34: 1205.85 | BD34: 1225.65 | BE34: 1245.45 | BF34: 1265.25 | BG34: 1285.05 | BH34: 1304.85 | BI34: 1324.65 | BJ34: 1344.45
A35: 根西岛 | B35: 7 | C35: =广诚DHL运费!I3 -> 192.60 | D35: =广诚DHL运费!I4 -> 242.70 | E35: =广诚DHL运费!I5 -> 292.80 | F35: =广诚DHL运费!I6 -> 342.90 | G35: =广诚DHL运费!I7 -> 393.00 | H35: =广诚DHL运费!I8 -> 446.10 | I35: =广诚DHL运费!I9 -> 499.20 | J35: =广诚DHL运费!I10 -> 552.30 | K35: =广诚DHL运费!I11 -> 605.40 | L35: =广诚DHL运费!I12 -> 658.50 | M35: =广诚DHL运费!I13 -> 706.50 | N35: =广诚DHL运费!I14 -> 754.50 | O35: =广诚DHL运费!I15 -> 802.50 | P35: =广诚DHL运费!I16 -> 850.50 | Q35: =广诚DHL运费!I17 -> 898.50 | R35: =广诚DHL运费!I18 -> 946.50 | S35: =广诚DHL运费!I19 -> 994.50 | T35: =广诚DHL运费!I20 -> 1,042.50 | U35: =广诚DHL运费!I21 -> 1,090.50 | V35: =广诚DHL运费!I22 -> 1,138.50 | W35: =广诚DHL运费!I23 -> 1,181.10 | X35: =广诚DHL运费!I24 -> 1,223.70 | Y35: =广诚DHL运费!I25 -> 1,266.30 | Z35: =广诚DHL运费!I26 -> 1,308.90 | AA35: =广诚DHL运费!I27 -> 1,351.50 | AB35: =广诚DHL运费!I28 -> 1,394.10 | AC35: =广诚DHL运费!I29 -> 1,436.70 | AD35: =广诚DHL运费!I30 -> 1,479.30 | AE35: =广诚DHL运费!I31 -> 1,521.90 | AF35: =广诚DHL运费!I32 -> 1,564.50 | AG35: =广诚DHL运费!I33 -> 1,607.10 | AH35: =广诚DHL运费!I34 -> 1,649.70 | AI35: =广诚DHL运费!I35 -> 1,692.30 | AJ35: =广诚DHL运费!I36 -> 1,734.90 | AK35: =广诚DHL运费!I37 -> 1,777.50 | AL35: =广诚DHL运费!I38 -> 1,820.10 | AM35: =广诚DHL运费!I39 -> 1,862.70 | AN35: =广诚DHL运费!I40 -> 1,905.30 | AO35: =广诚DHL运费!I41 -> 1,947.90 | AP35: =广诚DHL运费!I42 -> 1,990.50 | AQ35: 968.25 | AR35: 988.05 | AS35: 1007.85 | AT35: 1027.65 | AU35: 1047.45 | AV35: 1067.25 | AW35: 1087.05 | AX35: 1106.85 | AY35: 1126.65 | AZ35: 1146.45 | BA35: 1166.25 | BB35: 1186.05 | BC35: 1205.85 | BD35: 1225.65 | BE35: 1245.45 | BF35: 1265.25 | BG35: 1285.05 | BH35: 1304.85 | BI35: 1324.65 | BJ35: 1344.45
A36: 直布罗陀 | B36: 7 | C36: =广诚DHL运费!I3 -> 192.60 | D36: =广诚DHL运费!I4 -> 242.70 | E36: =广诚DHL运费!I5 -> 292.80 | F36: =广诚DHL运费!I6 -> 342.90 | G36: =广诚DHL运费!I7 -> 393.00 | H36: =广诚DHL运费!I8 -> 446.10 | I36: =广诚DHL运费!I9 -> 499.20 | J36: =广诚DHL运费!I10 -> 552.30 | K36: =广诚DHL运费!I11 -> 605.40 | L36: =广诚DHL运费!I12 -> 658.50 | M36: =广诚DHL运费!I13 -> 706.50 | N36: =广诚DHL运费!I14 -> 754.50 | O36: =广诚DHL运费!I15 -> 802.50 | P36: =广诚DHL运费!I16 -> 850.50 | Q36: =广诚DHL运费!I17 -> 898.50 | R36: =广诚DHL运费!I18 -> 946.50 | S36: =广诚DHL运费!I19 -> 994.50 | T36: =广诚DHL运费!I20 -> 1,042.50 | U36: =广诚DHL运费!I21 -> 1,090.50 | V36: =广诚DHL运费!I22 -> 1,138.50 | W36: =广诚DHL运费!I23 -> 1,181.10 | X36: =广诚DHL运费!I24 -> 1,223.70 | Y36: =广诚DHL运费!I25 -> 1,266.30 | Z36: =广诚DHL运费!I26 -> 1,308.90 | AA36: =广诚DHL运费!I27 -> 1,351.50 | AB36: =广诚DHL运费!I28 -> 1,394.10 | AC36: =广诚DHL运费!I29 -> 1,436.70 | AD36: =广诚DHL运费!I30 -> 1,479.30 | AE36: =广诚DHL运费!I31 -> 1,521.90 | AF36: =广诚DHL运费!I32 -> 1,564.50 | AG36: =广诚DHL运费!I33 -> 1,607.10 | AH36: =广诚DHL运费!I34 -> 1,649.70 | AI36: =广诚DHL运费!I35 -> 1,692.30 | AJ36: =广诚DHL运费!I36 -> 1,734.90 | AK36: =广诚DHL运费!I37 -> 1,777.50 | AL36: =广诚DHL运费!I38 -> 1,820.10 | AM36: =广诚DHL运费!I39 -> 1,862.70 | AN36: =广诚DHL运费!I40 -> 1,905.30 | AO36: =广诚DHL运费!I41 -> 1,947.90 | AP36: =广诚DHL运费!I42 -> 1,990.50 | AQ36: 968.25 | AR36: 988.05 | AS36: 1007.85 | AT36: 1027.65 | AU36: 1047.45 | AV36: 1067.25 | AW36: 1087.05 | AX36: 1106.85 | AY36: 1126.65 | AZ36: 1146.45 | BA36: 1166.25 | BB36: 1186.05 | BC36: 1205.85 | BD36: 1225.65 | BE36: 1245.45 | BF36: 1265.25 | BG36: 1285.05 | BH36: 1304.85 | BI36: 1324.65 | BJ36: 1344.45
A37: 格陵兰岛 | B37: 7 | C37: =广诚DHL运费!I3 -> 192.60 | D37: =广诚DHL运费!I4 -> 242.70 | E37: =广诚DHL运费!I5 -> 292.80 | F37: =广诚DHL运费!I6 -> 342.90 | G37: =广诚DHL运费!I7 -> 393.00 | H37: =广诚DHL运费!I8 -> 446.10 | I37: =广诚DHL运费!I9 -> 499.20 | J37: =广诚DHL运费!I10 -> 552.30 | K37: =广诚DHL运费!I11 -> 605.40 | L37: =广诚DHL运费!I12 -> 658.50 | M37: =广诚DHL运费!I13 -> 706.50 | N37: =广诚DHL运费!I14 -> 754.50 | O37: =广诚DHL运费!I15 -> 802.50 | P37: =广诚DHL运费!I16 -> 850.50 | Q37: =广诚DHL运费!I17 -> 898.50 | R37: =广诚DHL运费!I18 -> 946.50 | S37: =广诚DHL运费!I19 -> 994.50 | T37: =广诚DHL运费!I20 -> 1,042.50 | U37: =广诚DHL运费!I21 -> 1,090.50 | V37: =广诚DHL运费!I22 -> 1,138.50 | W37: =广诚DHL运费!I23 -> 1,181.10 | X37: =广诚DHL运费!I24 -> 1,223.70 | Y37: =广诚DHL运费!I25 -> 1,266.30 | Z37: =广诚DHL运费!I26 -> 1,308.90 | AA37: =广诚DHL运费!I27 -> 1,351.50 | AB37: =广诚DHL运费!I28 -> 1,394.10 | AC37: =广诚DHL运费!I29 -> 1,436.70 | AD37: =广诚DHL运费!I30 -> 1,479.30 | AE37: =广诚DHL运费!I31 -> 1,521.90 | AF37: =广诚DHL运费!I32 -> 1,564.50 | AG37: =广诚DHL运费!I33 -> 1,607.10 | AH37: =广诚DHL运费!I34 -> 1,649.70 | AI37: =广诚DHL运费!I35 -> 1,692.30 | AJ37: =广诚DHL运费!I36 -> 1,734.90 | AK37: =广诚DHL运费!I37 -> 1,777.50 | AL37: =广诚DHL运费!I38 -> 1,820.10 | AM37: =广诚DHL运费!I39 -> 1,862.70 | AN37: =广诚DHL运费!I40 -> 1,905.30 | AO37: =广诚DHL运费!I41 -> 1,947.90 | AP37: =广诚DHL运费!I42 -> 1,990.50 | AQ37: 968.25 | AR37: 988.05 | AS37: 1007.85 | AT37: 1027.65 | AU37: 1047.45 | AV37: 1067.25 | AW37: 1087.05 | AX37: 1106.85 | AY37: 1126.65 | AZ37: 1146.45 | BA37: 1166.25 | BB37: 1186.05 | BC37: 1205.85 | BD37: 1225.65 | BE37: 1245.45 | BF37: 1265.25 | BG37: 1285.05 | BH37: 1304.85 | BI37: 1324.65 | BJ37: 1344.45
A38: 希腊 | B38: 7 | C38: =广诚DHL运费!I3 -> 192.60 | D38: =广诚DHL运费!I4 -> 242.70 | E38: =广诚DHL运费!I5 -> 292.80 | F38: =广诚DHL运费!I6 -> 342.90 | G38: =广诚DHL运费!I7 -> 393.00 | H38: =广诚DHL运费!I8 -> 446.10 | I38: =广诚DHL运费!I9 -> 499.20 | J38: =广诚DHL运费!I10 -> 552.30 | K38: =广诚DHL运费!I11 -> 605.40 | L38: =广诚DHL运费!I12 -> 658.50 | M38: =广诚DHL运费!I13 -> 706.50 | N38: =广诚DHL运费!I14 -> 754.50 | O38: =广诚DHL运费!I15 -> 802.50 | P38: =广诚DHL运费!I16 -> 850.50 | Q38: =广诚DHL运费!I17 -> 898.50 | R38: =广诚DHL运费!I18 -> 946.50 | S38: =广诚DHL运费!I19 -> 994.50 | T38: =广诚DHL运费!I20 -> 1,042.50 | U38: =广诚DHL运费!I21 -> 1,090.50 | V38: =广诚DHL运费!I22 -> 1,138.50 | W38: =广诚DHL运费!I23 -> 1,181.10 | X38: =广诚DHL运费!I24 -> 1,223.70 | Y38: =广诚DHL运费!I25 -> 1,266.30 | Z38: =广诚DHL运费!I26 -> 1,308.90 | AA38: =广诚DHL运费!I27 -> 1,351.50 | AB38: =广诚DHL运费!I28 -> 1,394.10 | AC38: =广诚DHL运费!I29 -> 1,436.70 | AD38: =广诚DHL运费!I30 -> 1,479.30 | AE38: =广诚DHL运费!I31 -> 1,521.90 | AF38: =广诚DHL运费!I32 -> 1,564.50 | AG38: =广诚DHL运费!I33 -> 1,607.10 | AH38: =广诚DHL运费!I34 -> 1,649.70 | AI38: =广诚DHL运费!I35 -> 1,692.30 | AJ38: =广诚DHL运费!I36 -> 1,734.90 | AK38: =广诚DHL运费!I37 -> 1,777.50 | AL38: =广诚DHL运费!I38 -> 1,820.10 | AM38: =广诚DHL运费!I39 -> 1,862.70 | AN38: =广诚DHL运费!I40 -> 1,905.30 | AO38: =广诚DHL运费!I41 -> 1,947.90 | AP38: =广诚DHL运费!I42 -> 1,990.50 | AQ38: 968.25 | AR38: 988.05 | AS38: 1007.85 | AT38: 1027.65 | AU38: 1047.45 | AV38: 1067.25 | AW38: 1087.05 | AX38: 1106.85 | AY38: 1126.65 | AZ38: 1146.45 | BA38: 1166.25 | BB38: 1186.05 | BC38: 1205.85 | BD38: 1225.65 | BE38: 1245.45 | BF38: 1265.25 | BG38: 1285.05 | BH38: 1304.85 | BI38: 1324.65 | BJ38: 1344.45
A39: 克罗地亚 | B39: 7 | C39: =广诚DHL运费!I3 -> 192.60 | D39: =广诚DHL运费!I4 -> 242.70 | E39: =广诚DHL运费!I5 -> 292.80 | F39: =广诚DHL运费!I6 -> 342.90 | G39: =广诚DHL运费!I7 -> 393.00 | H39: =广诚DHL运费!I8 -> 446.10 | I39: =广诚DHL运费!I9 -> 499.20 | J39: =广诚DHL运费!I10 -> 552.30 | K39: =广诚DHL运费!I11 -> 605.40 | L39: =广诚DHL运费!I12 -> 658.50 | M39: =广诚DHL运费!I13 -> 706.50 | N39: =广诚DHL运费!I14 -> 754.50 | O39: =广诚DHL运费!I15 -> 802.50 | P39: =广诚DHL运费!I16 -> 850.50 | Q39: =广诚DHL运费!I17 -> 898.50 | R39: =广诚DHL运费!I18 -> 946.50 | S39: =广诚DHL运费!I19 -> 994.50 | T39: =广诚DHL运费!I20 -> 1,042.50 | U39: =广诚DHL运费!I21 -> 1,090.50 | V39: =广诚DHL运费!I22 -> 1,138.50 | W39: =广诚DHL运费!I23 -> 1,181.10 | X39: =广诚DHL运费!I24 -> 1,223.70 | Y39: =广诚DHL运费!I25 -> 1,266.30 | Z39: =广诚DHL运费!I26 -> 1,308.90 | AA39: =广诚DHL运费!I27 -> 1,351.50 | AB39: =广诚DHL运费!I28 -> 1,394.10 | AC39: =广诚DHL运费!I29 -> 1,436.70 | AD39: =广诚DHL运费!I30 -> 1,479.30 | AE39: =广诚DHL运费!I31 -> 1,521.90 | AF39: =广诚DHL运费!I32 -> 1,564.50 | AG39: =广诚DHL运费!I33 -> 1,607.10 | AH39: =广诚DHL运费!I34 -> 1,649.70 | AI39: =广诚DHL运费!I35 -> 1,692.30 | AJ39: =广诚DHL运费!I36 -> 1,734.90 | AK39: =广诚DHL运费!I37 -> 1,777.50 | AL39: =广诚DHL运费!I38 -> 1,820.10 | AM39: =广诚DHL运费!I39 -> 1,862.70 | AN39: =广诚DHL运费!I40 -> 1,905.30 | AO39: =广诚DHL运费!I41 -> 1,947.90 | AP39: =广诚DHL运费!I42 -> 1,990.50 | AQ39: 968.25 | AR39: 988.05 | AS39: 1007.85 | AT39: 1027.65 | AU39: 1047.45 | AV39: 1067.25 | AW39: 1087.05 | AX39: 1106.85 | AY39: 1126.65 | AZ39: 1146.45 | BA39: 1166.25 | BB39: 1186.05 | BC39: 1205.85 | BD39: 1225.65 | BE39: 1245.45 | BF39: 1265.25 | BG39: 1285.05 | BH39: 1304.85 | BI39: 1324.65 | BJ39: 1344.45
